Workbook

Sheet Gastos
A1: Media 2013 | B1: Media 2014 | C1: Media 2015 | D1: Media 2016 | E1: Gastos Fijos 2015 | F1: TOTAL Anual | G1: Total Comerc. | H1: Total Tiendas | I1: Total M.Free | J1: C.Enero | K1: T.Enero | L1: M.Enero | M1: Total Enero | N1: C.Febrero | O1: T.Febrero | P1: M.Febrero | Q1: Total Febrero | R1: C.Marzo | S1: T.Marzo | T1: M.Marzo | U1: Total Marzo | V1: C.Abril | W1: T.Abril | X1: M.Abril | Y1: Total Abril | Z1: C.Mayo | AA1: T.Mayo | AB1: M.Mayo | AC1: Total Mayo | AD1: C.Junio | AE1: T.Junio | AF1: M.Junio | AG1: Total Junio | AH1: C.Julio | AI1: T.Julio | AJ1: M.Julio | AK1: Total Julio | AL1: C.Agosto | AM1: T.Agosto | AN1: M.Agosto | AO1: Total Agosto | AP1: C.Septiem. | AQ1: T.Septiem. | AR1: M.Septiem. | AS1: Total Septiem. | AT1: C.Octubre | AU1: T.Octubre | AV1: M.Octubre | AW1: Total Octubre | AX1: C.Noviem. | AY1: T.Noviem. | AZ1: M.Noviem. | BA1: Total Noviem. | BB1: C.Diciem. | BC1: T.Diciem. | BD1: M.Diciem. | BE1: Total Diciem.
A2: 30502.2 | B2: 30428.2 | C2: 30416.98 | D2: =F2/12 -> 30763.153 | E2: Sueldos | F2: =M2+Q2+U2+Y2+AC2+AG2+AK2+AO2+AS2+AW2+BA2+BE2 -> 369157.84 | G2: =J2+N2+R2+V2+Z2+AD2+AH2+AL2+AP2+AT2+AX2+BB2 -> 152592.93 | H2: =K2+O2+S2+W2+AA2+AE2+AI2+AM2+AQ2+AU2+AY2+BC2 -> 197536.09 | I2: =L2+P2+T2+X2+AB2+AF2+AJ2+AN2+AR2+AV2+AZ2+BD2 -> 19028.82 | J2: 9500.61 | K2: 14095.83 | L2: 1355.27 | M2: =J2+K2+L2 -> 24951.71 | N2: 9500.61 | O2: 13859.62 | P2: 1355.27 | Q2: =N2+O2+P2 -> 24715.5 | R2: 9500.61 | S2: 14139.46 | T2: 1355.27 | U2: =R2+S2+T2 -> 24995.34 | V2: 11679.22 | W2: 14143.96 | X2: 1347.83 | Y2: =V2+W2+X2 -> 27171.01 | Z2: 10872.77 | AA2: 14735.03 | AB2: 1347.83 | AC2: =Z2+AA2+AB2 -> 26955.63 | AD2: 11190.01 | AE2: 13768.93 | AF2: 1398.44 | AG2: =AD2+AE2+AF2 -> 26357.38 | AH2: 20581.33 | AI2: 26313.48 | AJ2: 2705.52 | AK2: =AH2+AI2+AJ2 -> 49600.33 | AL2: 12234.82 | AM2: 15830.22 | AN2: 1371.16 | AO2: =AL2+AM2+AN2 -> 29436.2 | AP2: 11705.18 | AQ2: 15647.33 | AR2: 1371.16 | AS2: =AP2+AQ2+AR2 -> 28723.67 | AT2: 12079.18 | AU2: 14218.68 | AV2: 1371.16 | AW2: =AT2+AU2+AV2 -> 27669.02 | AX2: 12983.3 | AY2: 15133.08 | AZ2: 1371.16 | BA2: =AX2+AY2+AZ2 -> 29487.54 | BB2: 20765.29 | BC2: 25650.47 | BD2: 2678.75 | BE2: =BB2+BC2+BD2 -> 49094.51
A3: 8379.53 | B3: 8988.94 | C3: 8590.61 | D3: =F3/12 -> 9028.5742 | E3: Seguridad Social Empresa | F3: =M3+Q3+U3+Y3+AC3+AG3+AK3+AO3+AS3+AW3+BA3+BE3 -> 108342.89 | G3: =J3+N3+R3+V3+Z3+AD3+AH3+AL3+AP3+AT3+AX3+BB3 -> 47913.59 | H3: =K3+O3+S3+W3+AA3+AE3+AI3+AM3+AQ3+AU3+AY3+BC3 -> 59942.75 | I3: =L3+P3+T3+X3+AB3+AF3+AJ3+AN3+AR3+AV3+AZ3+BD3 -> 486.55 | J3: 3430.85 | K3: 4995.31 | L3: 34.26 | M3: =J3+K3+L3 -> 8460.42 | N3: 3430.85 | O3: 4863.6 | P3: 34.26 | Q3: =N3+O3+P3 -> 8328.71 | R3: 3430.85 | S3: 5008.95 | T3: 34.26 | U3: =R3+S3+T3 -> 8474.06 | V3: 3793.47 | W3: 5004.96 | X3: 32.63 | Y3: =V3+W3+X3 -> 8831.06 | Z3: 3635.76 | AA3: 5004.96 | AB3: 32.63 | AC3: =Z3+AA3+AB3 -> 8673.35 | AD3: 4032.28 | AE3: 4955 | AF3: 50.18 | AG3: =AD3+AE3+AF3 -> 9037.46 | AH3: 4032.28 | AI3: 4973 | AJ3: 50.18 | AK3: =AH3+AI3+AJ3 -> 9055.46 | AL3: 4382.61 | AM3: 5621.42 | AN3: 43.63 | AO3: =AL3+AM3+AN3 -> 10047.66 | AP3: 4382.61 | AQ3: 5203.03 | AR3: 43.63 | AS3: =AP3+AQ3+AR3 -> 9629.27 | AT3: 4312.61 | AU3: 4756.84 | AV3: 43.63 | AW3: =AT3+AU3+AV3 -> 9113.08 | AX3: 4501.21 | AY3: 4756.84 | AZ3: 43.63 | BA3: =AX3+AY3+AZ3 -> 9301.68 | BB3: 4548.21 | BC3: 4798.84 | BD3: 43.63 | BE3: =BB3+BC3+BD3 -> 9390.68
A4: 7078.55 | B4: 5971.87 | C4: 5292.21 | D4: =F4/12 -> 5349.9117 | E4: Arrendamientos | F4: =M4+Q4+U4+Y4+AC4+AG4+AK4+AO4+AS4+AW4+BA4+BE4 -> 64198.94 | G4: =J4+N4+R4+V4+Z4+AD4+AH4+AL4+AP4+AT4+AX4+BB4 -> 10485.6 | H4: =K4+O4+S4+W4+AA4+AE4+AI4+AM4+AQ4+AU4+AY4+BC4 -> 42913.34 | I4: =L4+P4+T4+X4+AB4+AF4+AJ4+AN4+AR4+AV4+AZ4+BD4 -> 10800 | J4: 873.8 | K4: 3540.9 | L4: 900 | M4: =J4+K4+L4 -> 5314.7 | N4: 873.8 | O4: 3540.9 | P4: 900 | Q4: =N4+O4+P4 -> 5314.7 | R4: 873.8 | S4: 3540.9 | T4: 900 | U4: =R4+S4+T4 -> 5314.7 | V4: 873.8 | W4: 3540.9 | X4: 900 | Y4: =V4+W4+X4 -> 5314.7 | Z4: 873.8 | AA4: 3540.9 | AB4: 900 | AC4: =Z4+AA4+AB4 -> 5314.7 | AD4: 873.8 | AE4: 3540.9 | AF4: 900 | AG4: =AD4+AE4+AF4 -> 5314.7 | AH4: 873.8 | AI4: 3540.9 | AJ4: 900 | AK4: =AH4+AI4+AJ4 -> 5314.7 | AL4: 873.8 | AM4: 3623.8 | AN4: 900 | AO4: =AL4+AM4+AN4 -> 5397.6 | AP4: 873.8 | AQ4: 3623.8 | AR4: 900 | AS4: =AP4+AQ4+AR4 -> 5397.6 | AT4: 873.8 | AU4: 3623.8 | AV4: 900 | AW4: =AT4+AU4+AV4 -> 5397.6 | AX4: 873.8 | AY4: 3627.82 | AZ4: 900 | BA4: =AX4+AY4+AZ4 -> 5401.62 | BB4: 873.8 | BC4: 3627.82 | BD4: 900 | BE4: =BB4+BC4+BD4 -> 5401.62
A5: 849.29 | B5: 579.41 | C5: 655.73 | D5: =F5/12 -> 660.05667 | E5: Luz | F5: =M5+Q5+U5+Y5+AC5+AG5+AK5+AO5+AS5+AW5+BA5+BE5 -> 7920.68 | G5: =J5+N5+R5+V5+Z5+AD5+AH5+AL5+AP5+AT5+AX5+BB5 -> 1207.22 | H5: =K5+O5+S5+W5+AA5+AE5+AI5+AM5+AQ5+AU5+AY5+BC5 -> 5856.34 | I5: =L5+P5+T5+X5+AB5+AF5+AJ5+AN5+AR5+AV5+AZ5+BD5 -> 857.12 | J5: 120.25 | K5: 484.99 | L5: 0 | M5: =J5+K5+L5 -> 605.24 | N5: 128.86 | O5: 493.96 | P5: 114.09 | Q5: =N5+O5+P5 -> 736.91 | R5: 86.9 | S5: 687.96 | T5: 74.87 | U5: =R5+S5+T5 -> 849.73 | V5: 131.62 | W5: 397.35 | X5: 77.82 | Y5: =V5+W5+X5 -> 606.79 | Z5: 80.42 | AA5: 520.66 | AB5: 74.58 | AC5: =Z5+AA5+AB5 -> 675.66 | AD5: 76.34 | AE5: 299.51 | AF5: 79.43 | AG5: =AD5+AE5+AF5 -> 455.28 | AH5: 88.12 | AI5: 617.71 | AJ5: 84.01 | AK5: =AH5+AI5+AJ5 -> 789.84 | AL5: 109.9 | AM5: 377.54 | AN5: 73.61 | AO5: =AL5+AM5+AN5 -> 561.05 | AP5: 109.69 | AQ5: 640.21 | AR5: 147.56 | AS5: =AP5+AQ5+AR5 -> 897.46 | AT5: 84.28 | AU5: 383.8 | AV5: 0 | AW5: =AT5+AU5+AV5 -> 468.08 | AX5: 79.21 | AY5: 754.75 | AZ5: 115.89 | BA5: =AX5+AY5+AZ5 -> 949.85 | BB5: 111.63 | BC5: 197.9 | BD5: 15.26 | BE5: =BB5+BC5+BD5 -> 324.79
A6: 837.9 | B6: 796.42 | C6: 667.77 | D6: =F6/12 -> 693.71083 | E6: Gasoil Solred | F6: =M6+Q6+U6+Y6+AC6+AG6+AK6+AO6+AS6+AW6+BA6+BE6 -> 8324.53 | G6: =J6+N6+R6+V6+Z6+AD6+AH6+AL6+AP6+AT6+AX6+BB6 -> 7547.64 | H6: =K6+O6+S6+W6+AA6+AE6+AI6+AM6+AQ6+AU6+AY6+BC6 -> 776.89 | I6: =L6+P6+T6+X6+AB6+AF6+AJ6+AN6+AR6+AV6+AZ6+BD6 -> 0 | J6: 541.94 | K6: 0 | L6: 0 | M6: =J6+K6+L6 -> 541.94 | N6: 660.64 | O6: 0 | P6: 0 | Q6: =N6+O6+P6 -> 660.64 | R6: 658.5 | S6: 0 | T6: 0 | U6: =R6+S6+T6 -> 658.5 | V6: 498.73 | W6: 0 | X6: 0 | Y6: =V6+W6+X6 -> 498.73 | Z6: 882.27 | AA6: 0 | AB6: 0 | AC6: =Z6+AA6+AB6 -> 882.27 | AD6: 990.69 | AE6: 0 | AF6: 0 | AG6: =AD6+AE6+AF6 -> 990.69 | AH6: 628.46 | AI6: 0 | AJ6: 0 | AK6: =AH6+AI6+AJ6 -> 628.46 | AL6: 706.77 | AM6: 0 | AN6: 0 | AO6: =AL6+AM6+AN6 -> 706.77 | AP6: 0 | AQ6: 776.89 | AR6: 0 | AS6: =AP6+AQ6+AR6 -> 776.89 | AT6: 763.29 | AU6: 0 | AV6: 0 | AW6: =AT6+AU6+AV6 -> 763.29 | AX6: 775.09 | AY6: 0 | AZ6: 0 | BA6: =AX6+AY6+AZ6 -> 775.09 | BB6: 441.26 | BC6: 0 | BD6: 0 | BE6: =BB6+BC6+BD6 -> 441.26
A7: 471.21 | B7: 394.88 | C7: 427.96 | D7: =F7/12 -> 433.07583 | E7: Teléfono Fijo | F7: =M7+Q7+U7+Y7+AC7+AG7+AK7+AO7+AS7+AW7+BA7+BE7 -> 5196.91 | G7: =J7+N7+R7+V7+Z7+AD7+AH7+AL7+AP7+AT7+AX7+BB7 -> 1636.4 | H7: =K7+O7+S7+W7+AA7+AE7+AI7+AM7+AQ7+AU7+AY7+BC7 -> 3176.98 | I7: =L7+P7+T7+X7+AB7+AF7+AJ7+AN7+AR7+AV7+AZ7+BD7 -> 383.53 | J7: 145.1 | K7: 301.02 | L7: 31.03 | M7: =J7+K7+L7 -> 477.15 | N7: 139.92 | O7: 213.19 | P7: 32.52 | Q7: =N7+O7+P7 -> 385.63 | R7: 148.92 | S7: 278.59 | T7: 34.4 | U7: =R7+S7+T7 -> 461.91 | V7: 124.31 | W7: 282.15 | X7: 37.13 | Y7: =V7+W7+X7 -> 443.59 | Z7: 145.92 | AA7: 214.09 | AB7: 23.94 | AC7: =Z7+AA7+AB7 -> 383.95 | AD7: 122.07 | AE7: 244.32 | AF7: 29.86 | AG7: =AD7+AE7+AF7 -> 396.25 | AH7: 119.45 | AI7: 241.92 | AJ7: 28.68 | AK7: =AH7+AI7+AJ7 -> 390.05 | AL7: 126.85 | AM7: 269.27 | AN7: 28.68 | AO7: =AL7+AM7+AN7 -> 424.8 | AP7: 151.89 | AQ7: 273.75 | AR7: 29.69 | AS7: =AP7+AQ7+AR7 -> 455.33 | AT7: 151.99 | AU7: 324.77 | AV7: 35.87 | AW7: =AT7+AU7+AV7 -> 512.63 | AX7: 128.81 | AY7: 265.94 | AZ7: 35.87 | BA7: =AX7+AY7+AZ7 -> 430.62 | BB7: 131.17 | BC7: 267.97 | BD7: 35.86 | BE7: =BB7+BC7+BD7 -> 435
A8: 445.93 | B8: 306.98 | C8: 330.28 | D8: =F8/12 -> 323.85833 | E8: Teléfono Móvil | F8: =M8+Q8+U8+Y8+AC8+AG8+AK8+AO8+AS8+AW8+BA8+BE8 -> 3886.3 | G8: =J8+N8+R8+V8+Z8+AD8+AH8+AL8+AP8+AT8+AX8+BB8 -> 2178.12 | H8: =K8+O8+S8+W8+AA8+AE8+AI8+AM8+AQ8+AU8+AY8+BC8 -> 1415.18 | I8: =L8+P8+T8+X8+AB8+AF8+AJ8+AN8+AR8+AV8+AZ8+BD8 -> 293 | J8: 167.65 | K8: 104.64 | L8: 22.65 | M8: =J8+K8+L8 -> 294.94 | N8: 172.65 | O8: 109.64 | P8: 22.65 | Q8: =N8+O8+P8 -> 304.94 | R8: 173.15 | S8: 113.44 | T8: 22.65 | U8: =R8+S8+T8 -> 309.24 | V8: 183.15 | W8: 123.44 | X8: 24.65 | Y8: =V8+W8+X8 -> 331.24 | Z8: 186.15 | AA8: 126.94 | AB8: 24.65 | AC8: =Z8+AA8+AB8 -> 337.74 | AD8: 186.15 | AE8: 126.04 | AF8: 24.25 | AG8: =AD8+AE8+AF8 -> 336.44 | AH8: 219.08 | AI8: 126.04 | AJ8: 24.25 | AK8: =AH8+AI8+AJ8 -> 369.37 | AL8: 193.15 | AM8: 132.04 | AN8: 24.25 | AO8: =AL8+AM8+AN8 -> 349.44 | AP8: 168.15 | AQ8: 107.04 | AR8: 24.25 | AS8: =AP8+AQ8+AR8 -> 299.44 | AT8: 175.15 | AU8: 114.04 | AV8: 26.25 | AW8: =AT8+AU8+AV8 -> 315.44 | AX8: 180.17 | AY8: 119.24 | AZ8: 26.25 | BA8: =AX8+AY8+AZ8 -> 325.66 | BB8: 173.52 | BC8: 112.64 | BD8: 26.25 | BE8: =BB8+BC8+BD8 -> 312.41
A9: 382.5 | B9: 390.84 | C9: 390.83 | D9: =F9/12 -> 378.33333 | E9: Asesoria Laboral | F9: =M9+Q9+U9+Y9+AC9+AG9+AK9+AO9+AS9+AW9+BA9+BE9 -> 4540 | G9: =J9+N9+R9+V9+Z9+AD9+AH9+AL9+AP9+AT9+AX9+BB9 -> 1587.1 | H9: =K9+O9+S9+W9+AA9+AE9+AI9+AM9+AQ9+AU9+AY9+BC9 -> 2697.53 | I9: =L9+P9+T9+X9+AB9+AF9+AJ9+AN9+AR9+AV9+AZ9+BD9 -> 255.37 | J9: 129.5 | K9: 222 | L9: 18.5 | M9: =J9+K9+L9 -> 370 | N9: 129.5 | O9: 222 | P9: 18.5 | Q9: =N9+O9+P9 -> 370 | R9: 129.5 | S9: 222 | T9: 18.5 | U9: =R9+S9+T9 -> 370 | V9: 129.5 | W9: 222 | X9: 18.5 | Y9: =V9+W9+X9 -> 370 | Z9: 129.5 | AA9: 222 | AB9: 18.5 | AC9: =Z9+AA9+AB9 -> 370 | AD9: 162.6 | AE9: 255.53 | AF9: 51.87 | AG9: =AD9+AE9+AF9 -> 470 | AH9: 129.5 | AI9: 222 | AJ9: 18.5 | AK9: =AH9+AI9+AJ9 -> 370 | AL9: 129.5 | AM9: 222 | AN9: 18.5 | AO9: =AL9+AM9+AN9 -> 370 | AP9: 129.5 | AQ9: 222 | AR9: 18.5 | AS9: =AP9+AQ9+AR9 -> 370 | AT9: 129.5 | AU9: 222 | AV9: 18.5 | AW9: =AT9+AU9+AV9 -> 370 | AX9: 129.5 | AY9: 222 | AZ9: 18.5 | BA9: =AX9+AY9+AZ9 -> 370 | BB9: 129.5 | BC9: 222 | BD9: 18.5 | BE9: =BB9+BC9+BD9 -> 370
A10: 175 | B10: 175 | C10: 170 | D10: =F10/12 -> 170 | E10: Abogado | F10: =M10+Q10+U10+Y10+AC10+AG10+AK10+AO10+AS10+AW10+BA10+BE10 -> 2040 | G10: =J10+N10+R10+V10+Z10+AD10+AH10+AL10+AP10+AT10+AX10+BB10 -> 714 | H10: =K10+O10+S10+W10+AA10+AE10+AI10+AM10+AQ10+AU10+AY10+BC10 -> 1224 | I10: =L10+P10+T10+X10+AB10+AF10+AJ10+AN10+AR10+AV10+AZ10+BD10 -> 102 | J10: 59.5 | K10: 102 | L10: 8.5 | M10: =J10+K10+L10 -> 170 | N10: 59.5 | O10: 102 | P10: 8.5 | Q10: =N10+O10+P10 -> 170 | R10: 59.5 | S10: 102 | T10: 8.5 | U10: =R10+S10+T10 -> 170 | V10: 59.5 | W10: 102 | X10: 8.5 | Y10: =V10+W10+X10 -> 170 | Z10: 59.5 | AA10: 102 | AB10: 8.5 | AC10: =Z10+AA10+AB10 -> 170 | AD10: 59.5 | AE10: 102 | AF10: 8.5 | AG10: =AD10+AE10+AF10 -> 170 | AH10: 59.5 | AI10: 102 | AJ10: 8.5 | AK10: =AH10+AI10+AJ10 -> 170 | AL10: 59.5 | AM10: 102 | AN10: 8.5 | AO10: =AL10+AM10+AN10 -> 170 | AP10: 59.5 | AQ10: 102 | AR10: 8.5 | AS10: =AP10+AQ10+AR10 -> 170 | AT10: 59.5 | AU10: 102 | AV10: 8.5 | AW10: =AT10+AU10+AV10 -> 170 | AX10: 59.5 | AY10: 102 | AZ10: 8.5 | BA10: =AX10+AY10+AZ10 -> 170 | BB10: 59.5 | BC10: 102 | BD10: 8.5 | BE10: =BB10+BC10+BD10 -> 170
A11: 115.38 | B11: 161.16 | C11: 277.69 | D11: =F11/12 -> 216.29417 | E11: Dietas JV y Coordinador | F11: =M11+Q11+U11+Y11+AC11+AG11+AK11+AO11+AS11+AW11+BA11+BE11 -> 2595.53 | G11: =J11+N11+R11+V11+Z11+AD11+AH11+AL11+AP11+AT11+AX11+BB11 -> 1030.24 | H11: =K11+O11+S11+W11+AA11+AE11+AI11+AM11+AQ11+AU11+AY11+BC11 -> 1565.29 | I11: =L11+P11+T11+X11+AB11+AF11+AJ11+AN11+AR11+AV11+AZ11+BD11 -> 0 | J11: 0 | K11: 200.5 | L11: 0 | M11: =J11+K11+L11 -> 200.5 | N11: 0 | O11: 140.3 | P11: 0 | Q11: =N11+O11+P11 -> 140.3 | R11: 0 | S11: 121.3 | T11: 0 | U11: =R11+S11+T11 -> 121.3 | V11: 87.75 | W11: 84.4 | X11: 0 | Y11: =V11+W11+X11 -> 172.15 | Z11: 96.55 | AA11: 122.8 | AB11: 0 | AC11: =Z11+AA11+AB11 -> 219.35 | AD11: 105.15 | AE11: 111.5 | AF11: 0 | AG11: =AD11+AE11+AF11 -> 216.65 | AH11: 30 | AI11: 203.4 | AJ11: 0 | AK11: =AH11+AI11+AJ11 -> 233.4 | AL11: 20 | AM11: 0 | AN11: 0 | AO11: =AL11+AM11+AN11 -> 20 | AP11: 255 | AQ11: 0 | AR11: 0 | AS11: =AP11+AQ11+AR11 -> 255 | AT11: 254.85 | AU11: 210.03 | AV11: 0 | AW11: =AT11+AU11+AV11 -> 464.88 | AX11: 88.94 | AY11: 150.23 | AZ11: 0 | BA11: =AX11+AY11+AZ11 -> 239.17 | BB11: 92 | BC11: 220.83 | BD11: 0 | BE11: =BB11+BC11+BD11 -> 312.83
A12: 80.42 | B12: 83.03 | C12: 62 | D12: =F12/12 -> 62 | E12: Limpieza de Cristales | F12: =M12+Q12+U12+Y12+AC12+AG12+AK12+AO12+AS12+AW12+BA12+BE12 -> 744 | G12: =J12+N12+R12+V12+Z12+AD12+AH12+AL12+AP12+AT12+AX12+BB12 -> 0 | H12: =K12+O12+S12+W12+AA12+AE12+AI12+AM12+AQ12+AU12+AY12+BC12 -> 562.56 | I12: =L12+P12+T12+X12+AB12+AF12+AJ12+AN12+AR12+AV12+AZ12+BD12 -> 181.44 | J12: 0 | K12: 46.88 | L12: 15.12 | M12: =J12+K12+L12 -> 62 | N12: 0 | O12: 46.88 | P12: 15.12 | Q12: =N12+O12+P12 -> 62 | R12: 0 | S12: 46.88 | T12: 15.12 | U12: =R12+S12+T12 -> 62 | V12: 0 | W12: 46.88 | X12: 15.12 | Y12: =V12+W12+X12 -> 62 | Z12: 0 | AA12: 46.88 | AB12: 15.12 | AC12: =Z12+AA12+AB12 -> 62 | AD12: 0 | AE12: 46.88 | AF12: 15.12 | AG12: =AD12+AE12+AF12 -> 62 | AH12: 0 | AI12: 46.88 | AJ12: 15.12 | AK12: =AH12+AI12+AJ12 -> 62 | AL12: 0 | AM12: 46.88 | AN12: 15.12 | AO12: =AL12+AM12+AN12 -> 62 | AP12: 0 | AQ12: 46.88 | AR12: 15.12 | AS12: =AP12+AQ12+AR12 -> 62 | AT12: 0 | AU12: 46.88 | AV12: 15.12 | AW12: =AT12+AU12+AV12 -> 62 | AX12: 0 | AY12: 46.88 | AZ12: 15.12 | BA12: =AX12+AY12+AZ12 -> 62 | BB12: 0 | BC12: 46.88 | BD12: 15.12 | BE12: =BB12+BC12+BD12 -> 62
A13: 79.25 | B13: 314.34 | C13: 301.01 | D13: =F13/12 -> 334.7175 | E13: Transportes | F13: =M13+Q13+U13+Y13+AC13+AG13+AK13+AO13+AS13+AW13+BA13+BE13 -> 4016.61 | G13: =J13+N13+R13+V13+Z13+AD13+AH13+AL13+AP13+AT13+AX13+BB13 -> 0 | H13: =K13+O13+S13+W13+AA13+AE13+AI13+AM13+AQ13+AU13+AY13+BC13 -> 3931.41 | I13: =L13+P13+T13+X13+AB13+AF13+AJ13+AN13+AR13+AV13+AZ13+BD13 -> 85.2 | J13: 0 | K13: 261.97 | L13: 5.8 | M13: =J13+K13+L13 -> 267.77 | N13: 0 | O13: 292.16 | P13: 5.8 | Q13: =N13+O13+P13 -> 297.96 | R13: 0 | S13: 239.1 | T13: 0 | U13: =R13+S13+T13 -> 239.1 | V13: 0 | W13: 524.2 | X13: 11.6 | Y13: =V13+W13+X13 -> 535.8 | Z13: 0 | AA13: 208.15 | AB13: 17.4 | AC13: =Z13+AA13+AB13 -> 225.55 | AD13: 0 | AE13: 291.33 | AF13: 0 | AG13: =AD13+AE13+AF13 -> 291.33 | AH13: 0 | AI13: 324.56 | AJ13: 0 | AK13: =AH13+AI13+AJ13 -> 324.56 | AL13: 0 | AM13: 320.37 | AN13: 11.6 | AO13: =AL13+AM13+AN13 -> 331.97 | AP13: 0 | AQ13: 277.43 | AR13: 0 | AS13: =AP13+AQ13+AR13 -> 277.43 | AT13: 0 | AU13: 515.07 | AV13: 11.6 | AW13: =AT13+AU13+AV13 -> 526.67 | AX13: 0 | AY13: 386.15 | AZ13: 11.6 | BA13: =AX13+AY13+AZ13 -> 397.75 | BB13: 0 | BC13: 290.92 | BD13: 9.8 | BE13: =BB13+BC13+BD13 -> 300.72
... A15: 40 | B15: 29.92 | C15: 21 | D15: =F15/12 -> 21 | E15: Comunidades | F15: =M15+Q15+U15+Y15+AC15+AG15+AK15+AO15+AS15+AW15+BA15+BE15 -> 252 | G15: =J15+N15+R15+V15+Z15+AD15+AH15+AL15+AP15+AT15+AX15+BB15 -> 0 | H15: =K15+O15+S15+W15+AA15+AE15+AI15+AM15+AQ15+AU15+AY15+BC15 -> 0 | I15: =L15+P15+T15+X15+AB15+AF15+AJ15+AN15+AR15+AV15+AZ15+BD15 -> 252 | J15: 0 | K15: 0 | L15: 21 | M15: =J15+K15+L15 -> 21 | N15: 0 | O15: 0 | P15: 21 | Q15: =N15+O15+P15 -> 21 | R15: 0 | S15: 0 | T15: 21 | U15: =R15+S15+T15 -> 21 | V15: 0 | W15: 0 | X15: 21 | Y15: =V15+W15+X15 -> 21 | Z15: 0 | AA15: 0 | AB15: 21 | AC15: =Z15+AA15+AB15 -> 21 | AD15: 0 | AE15: 0 | AF15: 21 | AG15: =AD15+AE15+AF15 -> 21 | AH15: 0 | AI15: 0 | AJ15: 21 | AK15: =AH15+AI15+AJ15 -> 21 | AL15: 0 | AM15: 0 | AN15: 21 | AO15: =AL15+AM15+AN15 -> 21 | AP15: 0 | AQ15: 0 | AR15: 21 | AS15: =AP15+AQ15+AR15 -> 21 | AT15: 0 | AU15: 0 | AV15: 21 | AW15: =AT15+AU15+AV15 -> 21 | AX15: 0 | AY15: 0 | AZ15: 21 | BA15: =AX15+AY15+AZ15 -> 21 | BB15: 0 | BC15: 0 | BD15: 21 | BE15: =BB15+BC15+BD15 -> 21
A16: 1082.71 | B16: 1082.72 | C16: 1029.01 | D16: =F16/12 -> 956.09667 | E16: Interes+Amort. Prestamo Piso | F16: =M16+Q16+U16+Y16+AC16+AG16+AK16+AO16+AS16+AW16+BA16+BE16 -> 11473.16 | G16: =J16+N16+R16+V16+Z16+AD16+AH16+AL16+AP16+AT16+AX16+BB16 -> 0 | H16: =K16+O16+S16+W16+AA16+AE16+AI16+AM16+AQ16+AU16+AY16+BC16 -> 0 | I16: =L16+P16+T16+X16+AB16+AF16+AJ16+AN16+AR16+AV16+AZ16+BD16 -> 0 | J16: 0 | K16: 0 | L16: 0 | M16: 975.99 | N16: 0 | O16: 0 | P16: 0 | Q16: 975.99 | R16: 0 | S16: 0 | T16: 0 | U16: 975.99 | V16: 0 | W16: 0 | X16: 0 | Y16: 975.99 | Z16: 0 | AA16: 0 | AB16: 0 | AC16: 975.99 | AD16: 0 | AE16: 0 | AF16: 0 | AG16: 975.99 | AH16: 0 | AI16: 0 | AJ16: 0 | AK16: 975.99 | AL16: 0 | AM16: 0 | AN16: 0 | AO16: 928.68 | AP16: 0 | AQ16: 0 | AR16: 0 | AS16: 928.68 | AT16: 0 | AU16: 0 | AV16: 0 | AW16: 928.68 | AX16: 0 | AY16: 0 | AZ16: 0 | BA16: 928.68 | BB16: 0 | BC16: 0 | BD16: 0 | BE16: 926.51
A17: 339.06 | B17: 186.85 | C17: 206.82 | D17: =F17/12 -> 250.48333 | E17: Adeslas (Angel Luis) | F17: =M17+Q17+U17+Y17+AC17+AG17+AK17+AO17+AS17+AW17+BA17+BE17 -> 3005.8 | G17: =J17+N17+R17+V17+Z17+AD17+AH17+AL17+AP17+AT17+AX17+BB17 -> 0 | H17: =K17+O17+S17+W17+AA17+AE17+AI17+AM17+AQ17+AU17+AY17+BC17 -> 0 | I17: =L17+P17+T17+X17+AB17+AF17+AJ17+AN17+AR17+AV17+AZ17+BD17 -> 0 | J17: 0 | K17: 0 | L17: 0 | M17: 254.15 | N17: 0 | O17: 0 | P17: 0 | Q17: 250.15 | R17: 0 | S17: 0 | T17: 0 | U17: 250.15 | V17: 0 | W17: 0 | X17: 0 | Y17: 250.15 | Z17: 0 | AA17: 0 | AB17: 0 | AC17: 250.15 | AD17: 0 | AE17: 0 | AF17: 0 | AG17: 250.15 | AH17: 0 | AI17: 0 | AJ17: 0 | AK17: 250.15 | AL17: 0 | AM17: 0 | AN17: 0 | AO17: 250.15 | AP17: 0 | AQ17: 0 | AR17: 0 | AS17: 250.15 | AT17: 0 | AU17: 0 | AV17: 0 | AW17: 250.15 | AX17: 0 | AY17: 0 | AZ17: 0 | BA17: 250.15 | BB17: 0 | BC17: 0 | BD17: 0 | BE17: 250.15
A18: 50920.35 | B18: 49918.69 | C18: =SUM(C2:C17) -> 48863.59 | D18: =SUM(D2:D17) -> 49664.819 | E18: Total gastos Fijos 2015 | F18: =M18+Q18+U18+Y18+AC18+AG18+AK18+AO18+AS18+AW18+BA18+BE18 -> 595977.83 | G18: =SUM(G2:G17) -> 226899.2 | H18: =SUM(H2:H17) -> 321874.64 | I18: =SUM(I2:I17) -> 32725.03 | J18: =SUM(J2:J17) -> 14975.56 | K18: =SUM(K2:K17) -> 24385.66 | L18: =SUM(L2:L17) -> 2412.13 | M18: =SUM(M2:M17) -> 43003.49 | N18: =SUM(N2:N17) -> 15096.33 | ... BE18: =SUM(BE2:BE17) -> 67817.36
A19: Variables | B19: Variables | C19: Variables | D19: Variables | E19: Gastos Variables | F19: TOTAL Anual | G19: Total Comerc. | H19: Total Tiendas | I19: Total M.Free | J19: C.Enero | K19: T.Enero | L19: M.Enero | M19: Total Enero | N19: C.Febrero | O19: T.Febrero | P19: M.Febrero | Q19: Total Febrero | R19: C.Marzo | S19: T.Marzo | T19: M.Marzo | U19: Total Marzo | V19: C.Abril | W19: T.Abril | X19: M.Abril | Y19: Total Abril | Z19: C.Mayo | AA19: T.Mayo | AB19: M.Mayo | AC19: Total Mayo | AD19: C.Junio | AE19: T.Junio | AF19: M.Junio | AG19: Total Junio | AH19: C.Julio | AI19: T.Julio | AJ19: M.Julio | AK19: Total Julio | AL19: C.Agosto | AM19: T.Agosto | AN19: M.Agosto | AO19: Total Agosto | AP19: C.Septiem. | AQ19: T.Septiem. | AR19: T.Septiem. | AS19: Total Septiem. | AT19: C.Octubre | AU19: T.Octubre | AV19: M.Octubre | AW19: Total Octubre | AX19: C.Noviem. | AY19: T.Noviem. | AZ19: M.Noviem. | BA19: Total Noviem. | BB19: C.Diciem. | BC19: T.Diciem. | BD19: M.Diciem. | BE19: Total Diciem.
A20: 2163.3 | B20: 872.54 | C20: 749.41 | D20: =F20/12 -> 409.04833 | E20: Arreglo Tiendas | F20: =M20+Q20+U20+Y20+AC20+AG20+AK20+AO20+AS20+AW20+BA20+BE20 -> 4908.58 | G20: =J20+N20+R20+V20+Z20+AD20+AH20+AL20+AP20+AT20+AX20+BB20 -> 228.36 | H20: =K20+O20+S20+W20+AA20+AE20+AI20+AM20+AQ20+AU20+AY20+BC20 -> 4437.22 | I20: =L20+P20+T20+X20+AB20+AF20+AJ20+AN20+AR20+AV20+AZ20+BD20 -> 243 | J20: 0 | K20: 0 | L20: 0 | M20: =J20+K20+L20 -> 0 | N20: 0 | O20: 173.67 | P20: 0 | Q20: =N20+O20+P20 -> 173.67 | R20: 0 | S20: 127.17 | T20: 0 | U20: =R20+S20+T20 -> 127.17 | V20: 0 | W20: 0 | X20: 0 | Y20: =V20+W20+X20 -> 0 | Z20: 0 | AA20: 830.58 | AB20: 0 | AC20: =Z20+AA20+AB20 -> 830.58 | AD20: 0 | AE20: 1380.15 | AF20: 0 | AG20: =AD20+AE20+AF20 -> 1380.15 | AH20: 0 | AI20: 235.53 | AJ20: 0 | AK20: =AH20+AI20+AJ20 -> 235.53 | AL20: 0 | AM20: 0 | AN20: 0 | AO20: =AL20+AM20+AN20 -> 0 | AP20: 15 | AQ20: 513.6 | AR20: 0 | AS20: =AP20+AQ20+AR20 -> 528.6 | AT20: 0 | AU20: 0 | AV20: 0 | AW20: =AT20+AU20+AV20 -> 0 | AX20: 213.36 | AY20: 346.71 | AZ20: 243 | BA20: =AX20+AY20+AZ20 -> 803.07 | BB20: 0 | BC20: 829.81 | BD20: 0 | BE20: =BB20+BC20+BD20 -> 829.81
A21: 1952.36 | B21: 141.08 | C21: 396.18 | D21: =F21/12 -> 269.75 | E21: Sueldos Fuera Nómi. (Idemni) | F21: =M21+Q21+U21+Y21+AC21+AG21+AK21+AO21+AS21+AW21+BA21+BE21 -> 3237 | G21: =J21+N21+R21+V21+Z21+AD21+AH21+AL21+AP21+AT21+AX21+BB21 -> 641.25 | H21: =K21+O21+S21+W21+AA21+AE21+AI21+AM21+AQ21+AU21+AY21+BC21 -> 2465.75 | I21: =L21+P21+T21+X21+AB21+AF21+AJ21+AN21+AR21+AV21+AZ21+BD21 -> 130 | J21: 54 | K21: 544 | L21: 40 | M21: =J21+K21+L21 -> 638 | N21: 60.75 | O21: 60.75 | P21: 0 | Q21: =N21+O21+P21 -> 121.5 | R21: 60.75 | S21: 190.75 | T21: 0 | U21: =R21+S21+T21 -> 251.5 | V21: 0 | W21: 94.5 | X21: 90 | Y21: =V21+W21+X21 -> 184.5 | Z21: 60.75 | AA21: 60.75 | AB21: 0 | AC21: =Z21+AA21+AB21 -> 121.5 | AD21: 60.75 | AE21: 60.75 | AF21: 0 | AG21: =AD21+AE21+AF21 -> 121.5 | AH21: 60.75 | AI21: 60.75 | AJ21: 0 | AK21: =AH21+AI21+AJ21 -> 121.5 | AL21: 60.75 | AM21: 60.75 | AN21: 0 | AO21: =AL21+AM21+AN21 -> 121.5 | AP21: 40.5 | AQ21: 40.5 | AR21: 0 | AS21: =AP21+AQ21+AR21 -> 81 | AT21: 60.75 | AU21: 940.75 | AV21: 0 | AW21: =AT21+AU21+AV21 -> 1001.5 | AX21: 60.75 | AY21: 60.75 | AZ21: 0 | BA21: =AX21+AY21+AZ21 -> 121.5 | BB21: 60.75 | BC21: 290.75 | BD21: 0 | BE21: =BB21+BC21+BD21 -> 351.5
A22: 549.63 | B22: 370.29 | C22: 838.5 | D22: =F22/12 -> 3197.2358 | E22: Impuestos (Basur, IBI, Circ.) | F22: =M22+Q22+U22+Y22+AC22+AG22+AK22+AO22+AS22+AW22+BA22+BE22 -> 38366.83 | G22: =J22+N22+R22+V22+Z22+AD22+AH22+AL22+AP22+AT22+AX22+BB22 -> 10638.08 | H22: =K22+O22+S22+W22+AA22+AE22+AI22+AM22+AQ22+AU22+AY22+BC22 -> 26377.49 | I22: =L22+P22+T22+X22+AB22+AF22+AJ22+AN22+AR22+AV22+AZ22+BD22 -> 1351.26 | J22: 0 | K22: 47.65 | L22: 0 | M22: =J22+K22+L22 -> 47.65 | N22: 0 | O22: 0 | P22: 0 | Q22: =N22+O22+P22 -> 0 | R22: 71.81 | S22: 105.01 | T22: 2.18 | U22: =R22+S22+T22 -> 179 | V22: 0 | W22: 47.65 | X22: 113.1 | Y22: =V22+W22+X22 -> 160.75 | Z22: 769.54 | AA22: 269.81 | AB22: 18.03 | AC22: =Z22+AA22+AB22 -> 1057.38 | AD22: 0 | AE22: 0 | AF22: 0 | AG22: =AD22+AE22+AF22 -> 0 | AH22: 2457.84 | AI22: 3425.28 | AJ22: 307.23 | AK22: =AH22+AI22+AJ22 -> 6190.35 | AL22: 0 | AM22: 7866.73 | AN22: 0 | AO22: =AL22+AM22+AN22 -> 7866.73 | AP22: 478.17 | AQ22: 742.24 | AR22: 53.13 | AS22: =AP22+AQ22+AR22 -> 1273.54 | AT22: 0 | AU22: 269.63 | AV22: 0 | AW22: =AT22+AU22+AV22 -> 269.63 | AX22: 6860.72 | AY22: 11148.67 | AZ22: 857.59 | BA22: =AX22+AY22+AZ22 -> 18866.98 | BB22: 0 | BC22: 2454.82 | BD22: 0 | BE22: =BB22+BC22+BD22 -> 2454.82
A23: 521.05 | B23: 553.22 | C23: 396.93 | D23: =F23/12 -> 183.06917 | E23: Publicidad | F23: =M23+Q23+U23+Y23+AC23+AG23+AK23+AO23+AS23+AW23+BA23+BE23 -> 2196.83 | G23: =J23+N23+R23+V23+Z23+AD23+AH23+AL23+AP23+AT23+AX23+BB23 -> 720.17 | H23: =K23+O23+S23+W23+AA23+AE23+AI23+AM23+AQ23+AU23+AY23+BC23 -> 1062.91 | I23: =L23+P23+T23+X23+AB23+AF23+AJ23+AN23+AR23+AV23+AZ23+BD23 -> 413.75 | J23: 0 | K23: 86.86 | L23: 0 | M23: =J23+K23+L23 -> 86.86 | N23: 0 | O23: 22.72 | P23: 119.59 | Q23: =N23+O23+P23 -> 142.31 | R23: 0 | S23: 0 | T23: 0 | U23: =R23+S23+T23 -> 0 | V23: 9.51 | W23: 0 | X23: 0 | Y23: =V23+W23+X23 -> 9.51 | Z23: 49.5 | AA23: 61.5 | AB23: 117 | AC23: =Z23+AA23+AB23 -> 228 | AD23: 0 | AE23: 0 | AF23: 0 | AG23: =AD23+AE23+AF23 -> 0 | AH23: 17.64 | AI23: 0 | AJ23: 0 | AK23: =AH23+AI23+AJ23 -> 17.64 | AL23: 0 | AM23: 0 | AN23: 0 | AO23: =AL23+AM23+AN23 -> 0 | AP23: 0 | AQ23: 0 | AR23: 25 | AS23: =AP23+AQ23+AR23 -> 25 | AT23: 0 | AU23: 20.16 | AV23: 78.51 | AW23: =AT23+AU23+AV23 -> 98.67 | AX23: 0 | AY23: 85.95 | AZ23: 0 | BA23: =AX23+AY23+AZ23 -> 85.95 | BB23: 643.52 | BC23: 785.72 | BD23: 73.65 | BE23: =BB23+BC23+BD23 -> 1502.89
A24: 470.6 | B24: 204.26 | C24: 560.93 | D24: =F24/12 -> 397.27083 | E24: Mantenimiento Vehiculos | F24: =M24+Q24+U24+Y24+AC24+AG24+AK24+AO24+AS24+AW24+BA24+BE24 -> 4767.25 | G24: =J24+N24+R24+V24+Z24+AD24+AH24+AL24+AP24+AT24+AX24+BB24 -> 3807.79 | H24: =K24+O24+S24+W24+AA24+AE24+AI24+AM24+AQ24+AU24+AY24+BC24 -> 885.66 | I24: =L24+P24+T24+X24+AB24+AF24+AJ24+AN24+AR24+AV24+AZ24+BD24 -> 73.8 | J24: 58.95 | K24: 0 | L24: 0 | M24: =J24+K24+L24 -> 58.95 | N24: 210.44 | O24: 0 | P24: 0 | Q24: =N24+O24+P24 -> 210.44 | R24: 0 | S24: 0 | T24: 0 | U24: =R24+S24+T24 -> 0 | V24: 1485.81 | W24: 885.66 | X24: 73.8 | Y24: =V24+W24+X24 -> 2445.27 | Z24: 0 | AA24: 0 | AB24: 0 | AC24: =Z24+AA24+AB24 -> 0 | AD24: 60.75 | AE24: 0 | AF24: 0 | AG24: =AD24+AE24+AF24 -> 60.75 | AH24: 143.91 | AI24: 0 | AJ24: 0 | AK24: =AH24+AI24+AJ24 -> 143.91 | AL24: 379.71 | AM24: 0 | AN24: 0 | AO24: =AL24+AM24+AN24 -> 379.71 | AP24: 796.94 | AQ24: 0 | AR24: 0 | AS24: =AP24+AQ24+AR24 -> 796.94 | AT24: 46.5 | AU24: 0 | AV24: 0 | AW24: =AT24+AU24+AV24 -> 46.5 | AX24: 564.78 | AY24: 0 | AZ24: 0 | BA24: =AX24+AY24+AZ24 -> 564.78 | BB24: 60 | BC24: 0 | BD24: 0 | BE24: =BB24+BC24+BD24 -> 60
A25: 379.48 | B25: 155.08 | C25: 128.02 | D25: =F25/12 -> 97.434167 | E25: Arsys Internet + Golden Soft | F25: =M25+Q25+U25+Y25+AC25+AG25+AK25+AO25+AS25+AW25+BA25+BE25 -> 1169.21 | G25: =J25+N25+R25+V25+Z25+AD25+AH25+AL25+AP25+AT25+AX25+BB25 -> 903.68 | H25: =K25+O25+S25+W25+AA25+AE25+AI25+AM25+AQ25+AU25+AY25+BC25 -> 259.88 | I25: =L25+P25+T25+X25+AB25+AF25+AJ25+AN25+AR25+AV25+AZ25+BD25 -> 5.65 | J25: 71.54 | K25: 16 | L25: 0 | M25: =J25+K25+L25 -> 87.54 | N25: 71.54 | O25: 16 | P25: 0 | Q25: =N25+O25+P25 -> 87.54 | R25: 71.54 | S25: 16 | T25: 0 | U25: =R25+S25+T25 -> 87.54 | V25: 116.74 | W25: 83.88 | X25: 5.65 | Y25: =V25+W25+X25 -> 206.27 | Z25: 71.54 | AA25: 16 | AB25: 0 | AC25: =Z25+AA25+AB25 -> 87.54 | AD25: 71.54 | AE25: 16 | AF25: 0 | AG25: =AD25+AE25+AF25 -> 87.54 | AH25: 71.54 | AI25: 16 | AJ25: 0 | AK25: =AH25+AI25+AJ25 -> 87.54 | AL25: 71.54 | AM25: 16 | AN25: 0 | AO25: =AL25+AM25+AN25 -> 87.54 | AP25: 71.54 | AQ25: 16 | AR25: 0 | AS25: =AP25+AQ25+AR25 -> 87.54 | AT25: 71.54 | AU25: 16 | AV25: 0 | AW25: =AT25+AU25+AV25 -> 87.54 | AX25: 71.54 | AY25: 16 | AZ25: 0 | BA25: =AX25+AY25+AZ25 -> 87.54 | BB25: 71.54 | BC25: 16 | BD25: 0 | BE25: =BB25+BC25+BD25 -> 87.54
A26: 288.25 | B26: 252.9 | C26: 453.73 | D26: =F26/12 -> 82.5325 | E26: Comisiones Tarjetas, etc | F26: =M26+Q26+U26+Y26+AC26+AG26+AK26+AO26+AS26+AW26+BA26+BE26 -> 990.39 | G26: =J26+N26+R26+V26+Z26+AD26+AH26+AL26+AP26+AT26+AX26+BB26 -> 0 | H26: =K26+O26+S26+W26+AA26+AE26+AI26+AM26+AQ26+AU26+AY26+BC26 -> 832.91 | I26: =L26+P26+T26+X26+AB26+AF26+AJ26+AN26+AR26+AV26+AZ26+BD26 -> 157.48 | J26: 0 | K26: 45.15 | L26: 6.87 | M26: =J26+K26+L26 -> 52.02 | N26: 0 | O26: 59.12 | P26: 20.05 | Q26: =N26+O26+P26 -> 79.17 | R26: 0 | S26: 48.08 | T26: 11.52 | U26: =R26+S26+T26 -> 59.6 | V26: 0 | W26: 45.46 | X26: 9.49 | Y26: =V26+W26+X26 -> 54.95 | Z26: 0 | AA26: 41.47 | AB26: 8.97 | AC26: =Z26+AA26+AB26 -> 50.44 | AD26: 0 | AE26: 95.5 | AF26: 9.27 | AG26: =AD26+AE26+AF26 -> 104.77 | AH26: 0 | AI26: 66.64 | AJ26: 20.41 | AK26: =AH26+AI26+AJ26 -> 87.05 | AL26: 0 | AM26: 207.2 | AN26: 20.25 | AO26: =AL26+AM26+AN26 -> 227.45 | AP26: 0 | AQ26: 69.79 | AR26: 11.84 | AS26: =AP26+AQ26+AR26 -> 81.63 | AT26: 0 | AU26: 67.05 | AV26: 14.61 | AW26: =AT26+AU26+AV26 -> 81.66 | AX26: 0 | AY26: 34.53 | AZ26: 9.35 | BA26: =AX26+AY26+AZ26 -> 43.88 | BB26: 0 | BC26: 52.92 | BD26: 14.85 | BE26: =BB26+BC26+BD26 -> 67.77
D27: =F27/12 -> 403.83408 | E27: Comisiones Bancarias | F27: =M27+Q27+U27+Y27+AC27+AG27+AK27+AO27+AS27+AW27+BA27+BE27 -> 4846.009 | G27: =J27+N27+R27+V27+Z27+AD27+AH27+AL27+AP27+AT27+AX27+BB27 -> 1784.73 | H27: =K27+O27+S27+W27+AA27+AE27+AI27+AM27+AQ27+AU27+AY27+BC27 -> 2824.709 | I27: =L27+P27+T27+X27+AB27+AF27+AJ27+AN27+AR27+AV27+AZ27+BD27 -> 236.57 | J27: 83.99 | K27: 131.94 | L27: 11.99 | M27: =J27+K27+L27 -> 227.92 | N27: 110.42 | O27: 173.41 | P27: 15.79 | Q27: =N27+O27+P27 -> 299.62 | R27: 494.98 | S27: 848.6 | T27: 70.71 | U27: =R27+S27+T27 -> 1414.29 | V27: 129.04 | W27: 193.56 | X27: 16.13 | Y27: =V27+W27+X27 -> 338.73 | Z27: 140.17 | AA27: 209.68 | AB27: 17.64 | AC27: =Z27+AA27+AB27 -> 367.49 | AD27: 128.62 | AE27: 192.849 | AF27: 16.12 | AG27: =AD27+AE27+AF27 -> 337.589 | AH27: 258.3 | AI27: 406.01 | AJ27: 36.91 | AK27: =AH27+AI27+AJ27 -> 701.22 | AL27: 89.68 | AM27: 129.48 | AN27: 9.96 | AO27: =AL27+AM27+AN27 -> 229.12 | AP27: 89.49 | AQ27: 129.23 | AR27: 9.94 | AS27: =AP27+AQ27+AR27 -> 228.66 | AT27: 89.01 | AU27: 132.01 | AV27: 10.01 | AW27: =AT27+AU27+AV27 -> 231.03 | AX27: 84.64 | AY27: 137.55 | AZ27: 10.58 | BA27: =AX27+AY27+AZ27 -> 232.77 | BB27: 86.39 | BC27: 140.39 | BD27: 10.79 | BE27: =BB27+BC27+BD27 -> 237.57
A28: 671.89 | B28: 671.89 | C28: 671.89 | D28: =F28/12 -> 0 | E28: Comisiones Zeleris | G28: =J28+N28+R28+V28+Z28+AD28+AH28+AL28+AP28+AT28+AX28+BB28 -> 0 | H28: =K28+O28+S28+W28+AA28+AE28+AI28+AM28+AQ28+AU28+AY28+BC28 -> 1720.18 | I28: =L28+P28+T28+X28+AB28+AF28+AJ28+AN28+AR28+AV28+AZ28+BD28 -> 0 | J28: 0 | K28: 573.33 | L28: 0 | M28: =J28+K28+L28 -> 573.33 | N28: 0 | O28: 496.54 | P28: 0 | Q28: =N28+O28+P28 -> 496.54 | R28: 0 | S28: 398.11 | T28: 0 | U28: =R28+S28+T28 -> 398.11 | V28: 0 | W28: 252.2 | X28: 0 | Y28: =V28+W28+X28 -> 252.2 | Z28: 0 | AA28: 0 | AB28: 0 | AC28: =Z28+AA28+AB28 -> 0 | AD28: 0 | AE28: 0 | AF28: 0 | AG28: =AD28+AE28+AF28 -> 0 | AH28: 0 | AI28: 0 | AJ28: 0 | AK28: =AH28+AI28+AJ28 -> 0 | AL28: 0 | AM28: 0 | AN28: 0 | AO28: =AL28+AM28+AN28 -> 0 | AP28: 0 | AQ28: 0 | AR28: 0 | AS28: =AP28+AQ28+AR28 -> 0 | AT28: 0 | AU28: 0 | AV28: 0 | AW28: =AT28+AU28+AV28 -> 0 | AX28: 0 | AY28: 0 | AZ28: 0 | BA28: =AX28+AY28+AZ28 -> 0 | BB28: 0 | BC28: 0 | BD28: 0 | BE28: =BB28+BC28+BD28 -> 0
A29: 235.54 | B29: 322.46 | C29: 190.84 | D29: =F29/12 -> 222.26833 | E29: Material de Oficina | F29: =M29+Q29+U29+Y29+AC29+AG29+AK29+AO29+AS29+AW29+BA29+BE29 -> 2667.22 | G29: =J29+N29+R29+V29+Z29+AD29+AH29+AL29+AP29+AT29+AX29+BB29 -> 611.41 | H29: =K29+O29+S29+W29+AA29+AE29+AI29+AM29+AQ29+AU29+AY29+BC29 -> 2033.13 | I29: =L29+P29+T29+X29+AB29+AF29+AJ29+AN29+AR29+AV29+AZ29+BD29 -> 22.68 | J29: 41.17 | K29: 142.23 | L29: 0 | M29: =J29+K29+L29 -> 183.4 | N29: 0 | O29: 111.59 | P29: 0 | Q29: =N29+O29+P29 -> 111.59 | R29: 0 | S29: 64.86 | T29: 4.31 | U29: =R29+S29+T29 -> 69.17 | V29: 0 | W29: 245.77 | X29: 0 | Y29: =V29+W29+X29 -> 245.77 | Z29: 0 | AA29: 180.17 | AB29: 0 | AC29: =Z29+AA29+AB29 -> 180.17 | AD29: 36.64 | AE29: 169.11 | AF29: 0 | AG29: =AD29+AE29+AF29 -> 205.75 | AH29: 0 | AI29: 187.34 | AJ29: 0 | AK29: =AH29+AI29+AJ29 -> 187.34 | AL29: 0 | AM29: 171.6 | AN29: 0 | AO29: =AL29+AM29+AN29 -> 171.6 | AP29: 291.62 | AQ29: 491.18 | AR29: 0 | AS29: =AP29+AQ29+AR29 -> 782.8 | AT29: 192.18 | AU29: 192.18 | AV29: 18.37 | AW29: =AT29+AU29+AV29 -> 402.73 | AX29: 0 | AY29: 27.3 | AZ29: 0 | BA29: =AX29+AY29+AZ29 -> 27.3 | BB29: 49.8 | BC29: 49.8 | BD29: 0 | BE29: =BB29+BC29+BD29 -> 99.6
A30: 218.56 | B30: 353.34 | C30: 492.05 | D30: =F30/12 -> 440.41083 | E30: Seguros Tiendas | F30: =M30+Q30+U30+Y30+AC30+AG30+AK30+AO30+AS30+AW30+BA30+BE30 -> 5284.93 | G30: =J30+N30+R30+V30+Z30+AD30+AH30+AL30+AP30+AT30+AX30+BB30 -> 319.25 | H30: =K30+O30+S30+W30+AA30+AE30+AI30+AM30+AQ30+AU30+AY30+BC30 -> 4313.71 | I30: =L30+P30+T30+X30+AB30+AF30+AJ30+AN30+AR30+AV30+AZ30+BD30 -> 651.97 | J30: 0 | K30: 0 | L30: 0 | M30: =J30+K30+L30 -> 0 | N30: 0 | O30: 0 | P30: 0 | Q30: =N30+O30+P30 -> 0 | R30: 0 | S30: 1871.27 | T30: 0 | U30: =R30+S30+T30 -> 1871.27 | V30: 133.76 | W30: 996.33 | X30: 16.72 | Y30: =V30+W30+X30 -> 1146.81 | Z30: 0 | AA30: 579.92 | AB30: 0 | AC30: =Z30+AA30+AB30 -> 579.92 | AD30: 0 | AE30: 587.99 | AF30: 0 | AG30: =AD30+AE30+AF30 -> 587.99 | AH30: 0 | AI30: 0 | AJ30: 0 | AK30: =AH30+AI30+AJ30 -> 0 | AL30: 128.61 | AM30: 185.77 | AN30: 14.29 | AO30: =AL30+AM30+AN30 -> 328.67 | AP30: 0 | AQ30: 0 | AR30: 0 | AS30: =AP30+AQ30+AR30 -> 0 | AT30: 0 | AU30: 0 | AV30: 0 | AW30: =AT30+AU30+AV30 -> 0 | AX30: 56.88 | AY30: 92.43 | AZ30: 7.11 | BA30: =AX30+AY30+AZ30 -> 156.42 | BB30: 0 | BC30: 0 | BD30: 613.85 | BE30: =BB30+BC30+BD30 -> 613.85
A31: 286.49 | B31: 465.25 | C31: 20.83 | D31: =F31/12 -> 245.94167 | E31: Varios (Multas,etc) | F31: =M31+Q31+U31+Y31+AC31+AG31+AK31+AO31+AS31+AW31+BA31+BE31 -> 2951.3 | G31: =J31+N31+R31+V31+Z31+AD31+AH31+AL31+AP31+AT31+AX31+BB31 -> 1113.73 | H31: =K31+O31+S31+W31+AA31+AE31+AI31+AM31+AQ31+AU31+AY31+BC31 -> 1709.72 | I31: =L31+P31+T31+X31+AB31+AF31+AJ31+AN31+AR31+AV31+AZ31+BD31 -> 127.85 | J31: 0 | K31: 0 | L31: 0 | M31: =J31+K31+L31 -> 0 | N31: 0 | O31: 0 | P31: 0 | Q31: =N31+O31+P31 -> 0 | R31: 0 | S31: 0 | T31: 0 | U31: =R31+S31+T31 -> 0 | V31: 17.15 | W31: 25.71 | X31: 2.14 | Y31: =V31+W31+X31 -> 45 | Z31: 0 | AA31: 0 | AB31: 0 | AC31: =Z31+AA31+AB31 -> 0 | AD31: 0 | AE31: 0 | AF31: 0 | AG31: =AD31+AE31+AF31 -> 0 | AH31: 0 | AI31: 50 | AJ31: 0 | AK31: =AH31+AI31+AJ31 -> 50 | AL31: 591.57 | AM31: 854.49 | AN31: 65.73 | AO31: =AL31+AM31+AN31 -> 1511.79 | AP31: 19.9 | AQ31: 28.6 | AR31: 2.2 | AS31: =AP31+AQ31+AR31 -> 50.7 | AT31: 206.93 | AU31: 298.89 | AV31: 22.99 | AW31: =AT31+AU31+AV31 -> 528.81 | AX31: 278.18 | AY31: 452.03 | AZ31: 34.79 | BA31: =AX31+AY31+AZ31 -> 765 | BB31: 0 | BC31: 0 | BD31: 0 | BE31: =BB31+BC31+BD31 -> 0
A32: 187.01 | B32: 151.64 | C32: 170.14 | D32: =F32/12 -> 201.70417 | E32: Seguros Automovil | F32: =M32+Q32+U32+Y32+AC32+AG32+AK32+AO32+AS32+AW32+BA32+BE32 -> 2420.45 | G32: =J32+N32+R32+V32+Z32+AD32+AH32+AL32+AP32+AT32+AX32+BB32 -> 2420.45 | H32: =K32+O32+S32+W32+AA32+AE32+AI32+AM32+AQ32+AU32+AY32+BC32 -> 0 | I32: =L32+P32+T32+X32+AB32+AF32+AJ32+AN32+AR32+AV32+AZ32+BD32 -> 0 | J32: 0 | K32: 0 | L32: 0 | M32: =J32+K32+L32 -> 0 | N32: 0 | O32: 0 | P32: 0 | Q32: =N32+O32+P32 -> 0 | R32: 0 | S32: 0 | T32: 0 | U32: =R32+S32+T32 -> 0 | V32: 970.66 | W32: 0 | X32: 0 | Y32: =V32+W32+X32 -> 970.66 | Z32: 236.6 | AA32: 0 | AB32: 0 | AC32: =Z32+AA32+AB32 -> 236.6 | AD32: 321.4 | AE32: 0 | AF32: 0 | AG32: =AD32+AE32+AF32 -> 321.4 | AH32: 311.46 | AI32: 0 | AJ32: 0 | AK32: =AH32+AI32+AJ32 -> 311.46 | AL32: 0 | AM32: 0 | AN32: 0 | AO32: =AL32+AM32+AN32 -> 0 | AP32: 0 | AQ32: 0 | AR32: 0 | AS32: =AP32+AQ32+AR32 -> 0 | AT32: 580.33 | AU32: 0 | AV32: 0 | AW32: =AT32+AU32+AV32 -> 580.33 | AX32: 0 | AY32: 0 | AZ32: 0 | BA32: =AX32+AY32+AZ32 -> 0 | BB32: 0 | BC32: 0 | BD32: 0 | BE32: =BB32+BC32+BD32 -> 0
A33: 86.35 | B33: 67.53 | C33: 100.68 | D33: =F33/12 -> 104.92 | E33: Mutua | F33: =M33+Q33+U33+Y33+AC33+AG33+AK33+AO33+AS33+AW33+BA33+BE33 -> 1259.04 | G33: =J33+N33+R33+V33+Z33+AD33+AH33+AL33+AP33+AT33+AX33+BB33 -> 473.1 | H33: =K33+O33+S33+W33+AA33+AE33+AI33+AM33+AQ33+AU33+AY33+BC33 -> 725.04 | I33: =L33+P33+T33+X33+AB33+AF33+AJ33+AN33+AR33+AV33+AZ33+BD33 -> 60.9 | J33: 51.24 | K33: 80.63 | L33: 7.33 | M33: =J33+K33+L33 -> 139.2 | N33: 0 | O33: 0 | P33: 0 | Q33: =N33+O33+P33 -> 0 | R33: 32.13 | S33: 55.08 | T33: 4.59 | U33: =R33+S33+T33 -> 91.8 | V33: 180.88 | W33: 271.32 | X33: 22.61 | Y33: =V33+W33+X33 -> 474.81 | Z33: 0 | AA33: 0 | AB33: 0 | AC33: =Z33+AA33+AB33 -> 0 | AD33: 0 | AE33: 0 | AF33: 0 | AG33: =AD33+AE33+AF33 -> 0 | AH33: 85.05 | AI33: 133.15 | AJ33: 12.15 | AK33: =AH33+AI33+AJ33 -> 230.35 | AL33: 0 | AM33: 0 | AN33: 0 | AO33: =AL33+AM33+AN33 -> 0 | AP33: 0 | AQ33: 0 | AR33: 0 | AS33: =AP33+AQ33+AR33 -> 0 | AT33: 90.36 | AU33: 130.52 | AV33: 10.04 | AW33: =AT33+AU33+AV33 -> 230.92 | AX33: 0 | AY33: 0 | AZ33: 0 | BA33: =AX33+AY33+AZ33 -> 0 | BB33: 33.44 | BC33: 54.34 | BD33: 4.18 | BE33: =BB33+BC33+BD33 -> 91.96
A34: 0 | B34: 0 | C34: 0 | D34: =F34/12 -> 319.04167 | E34: Penalizaciones Teléfonica | F34: =M34+Q34+U34+Y34+AC34+AG34+AK34+AO34+AS34+AW34+BA34+BE34 -> 3828.5 | G34: =J34+N34+R34+V34+Z34+AD34+AH34+AL34+AP34+AT34+AX34+BB34 -> 980 | H34: =K34+O34+S34+W34+AA34+AE34+AI34+AM34+AQ34+AU34+AY34+BC34 -> 2848.5 | I34: =L34+P34+T34+X34+AB34+AF34+AJ34+AN34+AR34+AV34+AZ34+BD34 -> 0 | J34: 250 | K34: 966.5 | L34: 0 | M34: =J34+K34+L34 -> 1216.5 | N34: 200 | O34: 420 | P34: 0 | Q34: =N34+O34+P34 -> 620 | R34: 0 | S34: 512 | T34: 0 | U34: =R34+S34+T34 -> 512 | V34: 80 | W34: 50 | X34: 0 | Y34: =V34+W34+X34 -> 130 | Z34: 0 | AA34: 100 | AB34: 0 | AC34: =Z34+AA34+AB34 -> 100 | AD34: 50 | AE34: 250 | AF34: 0 | AG34: =AD34+AE34+AF34 -> 300 | AH34: 400 | AI34: 550 | AJ34: 0 | AK34: =AH34+AI34+AJ34 -> 950 | AL34: 0 | AM34: 0 | AN34: 0 | AO34: =AL34+AM34+AN34 -> 0 | AP34: 0 | AQ34: 0 | AR34: 0 | AS34: =AP34+AQ34+AR34 -> 0 | AT34: 0 | AU34: 0 | AV34: 0 | AW34: =AT34+AU34+AV34 -> 0 | BA34: =AX34+AY34+AZ34 -> 0 | BE34: =BB34+BC34+BD34 -> 0
A35: 5683.96 | B35: 5142.09 | C35: 6800.17 | D35: =F35/12 -> 6126.2917 | E35: Salidas ALuis (Comisiones) | F35: =M35+Q35+U35+Y35+AC35+AG35+AK35+AO35+AS35+AW35+BA35+BE35 -> 73515.5 | G35: =J35+N35+R35+V35+Z35+AD35+AH35+AL35+AP35+AT35+AX35+BB35 -> 0 | H35: =K35+O35+S35+W35+AA35+AE35+AI35+AM35+AQ35+AU35+AY35+BC35 -> 0 | I35: =L35+P35+T35+X35+AB35+AF35+AJ35+AN35+AR35+AV35+AZ35+BD35 -> 0 | J35: 0 | K35: 0 | L35: 0 | M35: 6018 | N35: 0 | O35: 0 | P35: 0 | Q35: 6362 | R35: 0 | S35: 0 | T35: 0 | U35: 8270 | V35: 0 | W35: 0 | X35: 0 | Y35: 4810 | Z35: 0 | AA35: 0 | AB35: 0 | AC35: 8033 | AD35: 0 | AE35: 0 | AF35: 0 | AG35: 7563.5 | AH35: 0 | AI35: 0 | AJ35: 0 | AK35: 3346 | AL35: 0 | AM35: 0 | AN35: 0 | AO35: 3140 | AP35: 0 | AQ35: 0 | AR35: 0 | AS35: 4020 | AT35: 0 | AU35: 0 | AV35: 0 | AW35: 8110 | AX35: 0 | AY35: 0 | AZ35: 0 | BA35: 4060 | BB35: 0 | BC35: 0 | BD35: 0 | BE35: 9783
A36: 13028.99 | B36: 9051.68 | C36: =sum(C20:C35) -> 11970.3 | D36: =sum(D20:D35) -> 12700.753 | E36: Total Gastos Variables | F36: =M36+Q36+U36+Y36+AC36+AG36+AK36+AO36+AS36+AW36+BA36+BE36 -> 154129.22 | G36: =SUM(G20:G35) -> 24642 | H36: =SUM(H20:H35) -> 52496.809 | I36: =SUM(I20:I35) -> 3474.91 | J36: =SUM(J20:J35) -> 610.89 | K36: =SUM(K20:K35) -> 2634.29 | L36: =SUM(L20:L35) -> 66.19 | M36: =SUM(M20:M35) -> 9329.37 | N36: =SUM(N20:N35) -> 653.15 | ... BE36: =SUM(BE20:BE35) -> 16180.31
A37: =A18+A36 -> 63949.34 | B37: =B18+B36 -> 58970.37 | C37: 60080.65 | D37: =D18+D36 -> 62365.572 | E37: Total gastos Fijos + Variables | F37: =M37+Q37+U37+Y37+AC37+AG37+AK37+AO37+AS37+AW37+BA37+BE37 -> 750107.05 | G37: =G18+G36 -> 251541.2 | H37: =H18+H36 -> 374371.45 | I37: =I18+I36 -> 36199.94 | J37: =J18+J36 -> 15586.45 | K37: =K18+K36 -> 27019.95 | L37: =L18+L36 -> 2478.32 | M37: =M18+M36 -> 52332.86 | N37: =N18+N36 -> 15749.48 | ... BE37: =BE18+BE36 -> 83997.67
A38: =A37*12 -> 767392.08 | B38: =B37*12 -> 707644.44 | C38: =C37*12 -> 720967.8 | D38: =D37*12 -> 748386.87 | E38: Compras Mercaderias | F38: =M38+Q38+U38+Y38+AC38+AG38+AK38+AO38+AS38+AW38+BA38+BE38 -> 780016.79 | M38: 75482.45 | Q38: 60528.23 | U38: 52370.99 | Y38: 77015.97 | AC38: 64085.51 | AG38: 50353.64 | AK38: 45214.13 | AO38: 62094.97 | AS38: 103251.53 | AW38: 54591.03 | BA38: 58847.21 | BE38: 76181.13
E39: Total gastos General | F39: =M39+Q39+U39+Y39+AC39+AG39+AK39+AO39+AS39+AW39+BA39+BE39 -> 1530123.8 | M39: =M37+M38 -> 127815.31 | Q39: =Q37+Q38 -> 111997.74 | U39: =U37+U38 -> 108975.46 | Y39: =Y37+Y38 -> 134279.55 | AC39: =AC37+AC38 -> 121519.46 | AE39: 0 | AG39: =AG37+AG38 -> 106769.9 | AK39: =AK37+AK38 -> 126467.07 | AO39: =AO37+AO38 -> 125265.67 | AS39: =AS37+AS38 -> 159725.74 | AW39: =AW37+AW38 -> 113324.27 | BA39: =BA37+BA38 -> 133804.87 | BE39: =BE37+BE38 -> 160178.8
E40: Ventas Mercaderias | M40: 138266.74 | Q40: 116626 | U40: 108935 | Y40: 122705 | AC40: 122287.4 | AG40: 126875.09 | AK40: 111192.5 | AO40: 119492.23 | AS40: 115456.52 | AW40: 123579.94 | BA40: 124000 | BE40: 124873.66
E41: Beneficio o Perdida | F41: =M41+Q41+U41+Y41+AC41+AG41+AK41+AO41+AS41+AW41+BA41+BE41 -> -75833.759 | M41: =M40-M39 -> 10451.43 | Q41: =Q40-Q39 -> 4628.26 | U41: =U40-U39 -> -40.46 | Y41: =Y40-Y39 -> -11574.55 | AC41: =AC40-AC39 -> 767.94 | AG41: =AG40-AG39 -> 20105.191 | AK41: =AK40-AK39 -> -15274.57 | AO41: =AO40-AO39 -> -5773.44 | AS41: =AS40-AS39 -> -44269.22 | AW41: =AW40-AW39 -> 10255.67 | BA41: =BA40-BA39 -> -9804.87 | BE41: =BE40-BE39 -> -35305.14

Sheet Luz
A1: iberdrola.es | D1: 2106 | P1: 2017
A2: Usuario: CRCHAMSA | B2: Potencia | C2: Diciembre | D2: Enero | E2: Febrero | F2: Marzo | G2: Abril | H2: Mayo | I2: Junio | J2: Julio | K2: Agosto | L2: Septiembre | M2: Octubre | N2: Noviembre | O2: Diciembre | P2: Enero | Q2: Promedio MES | R2: Media Diaria | S2: Luz Asignada
A3: Contraseña: xa253625
A4: Estación KW | B4: 13.856 | C4: 1213 | D4: 1200 | E4: 1352 | F4: 911 | G4: 1324 | H4: 740 | I4: 683 | J4: 848 | K4: 1153 | L4: 1100 | M4: 794 | N4: 597 | O4: 952 | Q4: =SUM(C4:N4)/12 -> 992.91667 | R4: =Q4/25 -> 39.716667 | S4: 34
A5: Estación Importe | B5: =(B4*0.128398)*30 -> 53.372481 | C5: 310.04 | D5: 291.01 | E5: 311.83 | F5: 210.31 | G5: 318.52 | H5: 194.6 | I5: 184.75 | J5: 213.26 | K5: 265.95 | L5: 265.44 | M5: 203.95 | N5: 191.7 | O5: 223.26 | Q5: 246.78 | R5: 8.23
A7: Vitigudino KW | B7: 3.45 | D7: 974 | F7: 2468 | H7: 1800 | J7: 1993 | L7: 1369 | M7: 779 | N7: 1493 | O7: 188 | Q7: =SUM(C7:N7)/12 -> 906.33333 | R7: =Q7/25 -> 36.253333 | S7: 14
A8: Vitigudino Importe | B8: =(B7*0.114873)*30 -> 11.889356 | D8: 223.21 | F8: 445.27 | H8: 339.57 | J8: 395.53 | L8: 262.52 | M8: 152.96 | N8: 257.76 | O8: 26.81 | Q8: 182.35 | R8: 6.08
A10: Santa Marta KW | B10: 6.9 | C10: 750 | D10: 763 | E10: 654 | F10: 549 | G10: 569 | H10: 519 | I10: 438 | J10: 506 | K10: 675 | L10: 653 | M10: 546 | N10: 869 | O10: 81 | Q10: =SUM(C10:N10)/12 -> 624.25 | R10: =Q10/25 -> 24.97 | S10: 9
A11: Santa Marta Importe | B11: =(B10*0.114873)*30 -> 23.778711 | C11: 230.29 | D11: 218.13 | E11: 188.97 | F11: 159.32 | G11: 169.68 | H11: 163.37 | I11: 140.14 | J11: 156.51 | K11: 192.6 | L11: 179.59 | M11: 174.52 | N11: 298.82 | O11: 34.92 | Q11: 180.67 | R11: 6.02
A13: MovilFree KW | B13: 4.6 | C13: 396 | E13: 661 | F13: 457 | G13: 459 | H13: 427 | I13: 432 | J13: 482 | K13: 433 | L13: 431 | M13: 416 | N13: 676 | Q13: =SUM(C13:N13)/12 -> 439.16667 | R13: =Q13/25 -> 17.566667 | S13: 11
A14: MovilFree Importe | B14: =(B13*0.114873)*30 -> 15.852474 | C14: 83.9 | E14: 138.05 | F14: 90.59 | G14: 94.16 | H14: 90.24 | I14: 96.15 | J14: 101.65 | K14: 89.07 | L14: 90.42 | M14: 88.12 | N14: 131.23 | Q14: 82.52 | R14: 2.75
A16: Correhuela KW | B16: 3.45 | C16: 323 | E16: 675 | F16: 346 | G16: 445 | H16: 282 | I16: 228 | J16: 214 | K16: 92 | L16: 219 | M16: 187 | N16: 192 | O16: 253 | Q16: =SUM(C16:N16)/12 -> 266.91667 | R16: =Q16/25 -> 10.676667 | S16: 11
A17: Correhuela Importe | B17: =(B16*0.114873)*30 -> 11.889356 | C17: 90.01 | E17: 177.36 | F17: 83.01 | G17: 111.56 | H17: 83.64 | I17: 83.95 | J17: 75.95 | K17: 88.23 | L17: 75.67 | M17: 67.98 | N17: 78.59 | O17: 63.36 | Q17: 78.41 | R17: 2.61
A19: Peñaranda KW | B19: 3.45 | C19: 202 | E19: 364 | F19: 196 | G19: 165 | H19: 79 | I19: 49 | J19: 115 | K19: 174 | L19: 217 | M19: 105 | N19: 237 | O19: 155 | Q19: =SUM(C19:N19)/12 -> 158.58333 | R19: =Q19/25 -> 6.3433333 | S19: 8
A20: Peñaranda Importe | B20: =(B19*0.114873)*30 -> 11.889356 | C20: 46.22 | E20: 75.44 | F20: 39.69 | G20: 40.33 | H20: 29.74 | I20: 34.92 | J20: 36.57 | K20: 43.02 | L20: 56.17 | M20: 34.94 | N20: 52.67 | O20: 28.09 | Q20: 39.78 | R20: 1.33
A22: Total Kw Consumidos | C22: =C4+C7+C10+C13+C16+C19 -> 2884 | D22: =D4+D7+D10+D13+D16+D19 -> 2937 | E22: =E4+E7+E10+E13+E16+E19 -> 3706 | F22: =F4+F7+F10+F13+F16+F19 -> 4927 | G22: =G4+G7+G10+G13+G16+G19 -> 2962 | H22: =H4+H7+H10+H13+H16+H19 -> 3847 | I22: =I4+I7+I10+I13+I16+I19 -> 1830 | J22: =J4+J7+J10+J13+J16+J19 -> 4158 | ... N22: =N4+N7+N10+N13+N16+N19 -> 4064 | Q22: =Q4+Q7+Q10+Q13+Q16+Q19 -> 3388.1667 | R22: =R4+R7+R10+R13+R16+R19 -> 135.52667 | S22: =S4+S7+S10+S13+S16+S19 -> 87
A23: Total Factura | B23: =B5+B8+B11+B14+B17+B20 -> 128.67173 | C23: =C5+C8+C11+C14+C17+C20 -> 760.46 | D23: =D5+D8+D11+D14+D17+D20 -> 732.35 | E23: =E5+E8+E11+E14+E17+E20 -> 891.65 | F23: =F5+F8+F11+F14+F17+F20 -> 1028.19 | G23: =G5+G8+G11+G14+G17+G20 -> 734.25 | H23: =H5+H8+H11+H14+H17+H20 -> 901.16 | I23: =I5+I8+I11+I14+I17+I20 -> 539.91 | ... N23: =N5+N8+N11+N14+N17+N20 -> 1010.77 | Q23: =Q5+Q8+Q11+Q14+Q17+Q20 -> 810.51 | R23: =R5+R8+R11+R14+R17+R20 -> 27.02
D24: Estación: TRIFÁSICO | G24: Santa Marta: TRIFÁSICO | J24: Vitigudino: | M24: Correhuela : | P24: MovilFree : | S24: Peñaranda :
C25: domingo | D25: 42694 | E25: 8.33 | G25: 42694 | H25: 19.77 | J25: 42694 | K25: 13.2 | M25: 42694 | N25: 3.2 | P25: 42694 | Q25: 4.58 | S25: 42694 | T25: 2.25
C26: Lunes | D26: 42695 | E26: 40.1 | F26: 44.52 | G26: 42695 | H26: 13.09 | I26: 11.32 | J26: 42695 | K26: 18.1 | L26: 18.75 | M26: 42695 | N26: 13.5 | O26: 1.41 | P26: 42695 | Q26: 13.51 | R26: 13.15 | S26: 42695 | T26: 9.32 | U26: 11.65
C27: martes | D27: 42696 | E27: 49.59 | F27: 40.11 | G27: 42696 | H27: 13.26 | I27: 10.54 | J27: 42696 | K27: 3.06 | L27: 20.22 | M27: 42696 | N27: 12.94 | O27: 25 | P27: 42696 | Q27: 13.26 | R27: 13.69 | S27: 42696 | T27: 1.24 | U27: 10.99
C28: miércoles | D28: 42697 | E28: 43.5 | F28: 38.86 | G28: 42697 | H28: 17.58 | I28: 10.41 | J28: 42697 | K28: 13.47 | L28: 16.55 | M28: 42697 | N28: 13.2 | O28: 12.71 | P28: 42697 | Q28: 13.02 | R28: 12.75 | S28: 42697 | T28: 11.66 | U28: 9.65
C29: jueves | D29: 42698 | E29: 44.81 | F29: 38.74 | G29: 42698 | H29: 19.72 | I29: 10.36 | J29: 42698 | K29: 16.99 | L29: 15.05 | M29: 42698 | N29: 13.16 | O29: 13.1 | P29: 42698 | Q29: 13.47 | R29: 12.4 | S29: 42698 | T29: 11.81 | U29: 9.18
C30: viernes | D30: 42699 | E30: 44.29 | F30: 35.4 | G30: 42699 | H30: 20.86 | I30: 8.57 | J30: 42699 | K30: 18.61 | L30: 16.87 | M30: 42699 | N30: 13.3 | O30: 12.69 | P30: 42699 | Q30: 13.34 | R30: 12.8 | S30: 42699 | T30: 11.94 | U30: 8.6
C31: sábado | D31: 42700 | E31: 21.28 | F31: 20.92 | G31: 42700 | H31: 10.4 | I31: 7.2 | J31: 42700 | K31: 9.24 | L31: 9.94 | M31: 42700 | N31: 8.31 | O31: 8.08 | P31: 42700 | Q31: 8.55 | R31: 8.92 | S31: 42700 | T31: 6.11 | U31: 4.62
C32: domingo | D32: 42701 | E32: 5.48 | F32: 5.47 | G32: 42701 | H32: 2.8 | I32: 2.96 | J32: 42701 | K32: 1.26 | L32: 1.26 | M32: 42701 | N32: 2.61 | O32: 2.5 | P32: 42701 | Q32: 3.97 | R32: 3.66 | S32: 42701 | T32: 0.71 | U32: 0.71
C33: Total | E33: =SUM(E26:E32) -> 249.05 | F33: =SUM(F26:F32) -> 224.02 | H33: =SUM(H26:H32) -> 97.71 | I33: =SUM(I26:I32) -> 61.36 | K33: =SUM(K26:K32) -> 80.73 | L33: =SUM(L26:L32) -> 98.64 | N33: =SUM(N26:N32) -> 77.02 | O33: =SUM(O26:O32) -> 75.49 | Q33: =SUM(Q26:Q32) -> 79.12 | R33: =SUM(R26:R32) -> 77.37 | T33: =SUM(T26:T32) -> 52.79 | U33: =SUM(U26:U32) -> 55.4
F34: =F33/7*30 -> 960.08571 | I34: =I33/7*30 -> 262.97143 | L34: =L33/7*30 -> 422.74286 | O34: =O33/7*30 -> 323.52857 | R34: =R33/7*30 -> 331.58571 | U34: =U33/7*30 -> 237.42857
M36: =(F33+I33+L33+O33+R33+U33)/7*30 -> 2538.3429 | N36: 0.11799 | O36: =M36*N36 -> 299.49907
M37: 4064 | N37: 0.127261 | O37: =M37*N37 -> 517.1887

Sheet Teléfono
A1: https://www.movistar.es/mi-movistar/ | E1: Usuario: B37290293 Contraseña: 1111AAAA | F1: Factura del 11 de Noviembre 2016 | G1: Factura del 11 de Diciembre 2016 | H1: Factura del 11 de Enero 2017
A2: Tienda | B2: Contratos | C2: Fijo | D2: Móvil | E2: Tipo Contrato Fijo ó Móvil
A3: Correhuela | B3: RTB y ADSL | C3: 923264998 | E3: RTB+FIBRA 50MB / 5MB + Llamadas a Fijos | F3: 44.67
A4: MovilFree | C4: 923214407 | E4: RTB+FIBRA 50MB / 5MB + Llamadas a Fijos | F4: 43.4
A5: Vitigudino | C5: 923500500 | E5: RTB+ADSL 10MB + Llamadas a Fijos (Hasta el 15 de Febrero de 2017 50%) | F5: 34.7
A6: Peñaranda | C6: 923543095 | E6: RTB+ADSL 10MB + Llamadas a Fijos | F6: 42.82
A7: Santa Marta | C7: 923332290 | E7: RTB+FIBRA 50MB / 5MB + Llamadas a Fijos | F7: 43.54
A8: Estación | C8: 923230939 | E8: RTB+FIBRA 300MB + Llamadas a Fijos + Móviles (Fibra NO Tiene Descuentos) | F8: 57.75
A9: Estación RDSI* | C9: 923125347 | E9: RDSI+ADSL 10MB + BONO + Bono llamadas a Fijos (RDSI NO Tiene Descuentos) | F9: 92.67
A10: Estación DDI Voz | C10: 923226212 | E10: Número Virtual (DDi NO Tiene Descuentos) | F10: 0
A11: Principe de Vergara/ Diego | B11: Fusión TV+ 4 | C11: 923185610 | D11: 639843010 | E11: FUSION+4 Línea Principal (ilimitadas Ext y 1000 int + 3Gb Datos) | F11: 161
A12: Angel Luis | D12: 619110112 | E12: FUSION+4 Línea Adicional (ilimitadas Ext y 1000 int + 3Gb Datos)
A13: Salva | D13: 636991853 | E13: FUSION+4 Línea Adicional (ilimitadas Ext y 1000 int + 3Gb Datos)
A14: Angelete | D14: 638168461 | E14: FUSION+4 Línea Adicional (ilimitadas Ext y 1000 int + 3Gb Datos)
A15: Juan Carlos | B15: FUSION EMPRESAS 2014 | D15: 616481284 | E15: TARIFA 20 CON ADSL/FIBRA (ilimitadas Ext y 1000 int + 2Gb Datos) | F15: 387.1
A16: Gabriel | D16: 608082959 | E16: TARIFA 20 CON ADSL/FIBRA (ilimitadas Ext y 1000 int + 2Gb Datos)
A17: Juan António | D17: 646571799 | E17: TARIFA 20 CON ADSL/FIBRA (ilimitadas Ext y 1000 int + 2Gb Datos)
A18: Javier | D18: 636991850 | E18: TARIFA 20 CON ADSL/FIBRA (ilimitadas Ext y 1000 int + 2Gb Datos)
A19: Marcos | D19: 628176776 | E19: TARIFA 20 CON ADSL/FIBRA (ilimitadas Ext y 1000 int + 2Gb Datos)
A20: Vicente | D20: 626460568 | E20: TARIFA 20 CON ADSL/FIBRA (ilimitadas Ext y 1000 int + 2Gb Datos)
A21: Andrés | D21: 616481282 | E21: TARIFA 20 CON ADSL/FIBRA (ilimitadas Ext y 1000 int + 2Gb Datos)
A22: MovilFree | D22: 626056199 | E22: TARIFA 20 CON ADSL/FIBRA (ilimitadas Ext y 1000 int + 2Gb Datos)
A23: Vitigudino | D23: 609030055 | E23: TARIFA 20 CON ADSL/FIBRA (ilimitadas Ext y 1000 int + 2Gb Datos)
A24: Peñaranda | D24: 628686492 | E24: TARIFA 20 CON ADSL/FIBRA (ilimitadas Ext y 1000 int + 2Gb Datos)
A25: Estación | D25: 636991851 | E25: TARIFA 30 CON ADSL/FIBRA (ilimitadas Ext y 1000 int + 4Gb Datos + MultiSim)
A26: Correhuela | D26: 616481281 | E26: TARIFA 10 CON ADSL/FIBRA (100 min Ext y 1000 int + 100Mb Datos)
A27: Santa Marta | D27: 650380024 | E27: TARIFA 10 CON ADSL/FIBRA (100 min Ext y 1000 int + 100Mb Datos)
... A31: Padre | D31: 605614460 | E31: TARIFA 5 CON ADSL/FIBRA (10 cts/min + establecimiento, SMS 15 cts)
A32: Total | F32: =SUM(F3:F31)/1.21 -> 750.12397 | G32: =SUM(G3:G31)/1.21 -> 0 | H32: =SUM(H3:H31)/1.21 -> 0

Sheet Ingresos
A1: INGRESOS 2016 | C1: Total | D1: Nacional + Contractual | H1: Nacional | AD1: Territorial | AO1: Otras comisiones / Caja | AY1: MovilFree
D2: Alta ADSL / F300 | E2: Contrato / Migra AV | F2: Contrato MV | G2: Contrato / Migra BV | H2: Migra F300 | I2: Migra F300 / MFE | J2: TV AV | K2: TV MV | L2: TV BV | M2: MFE XDSL | N2: MFE FTTH | O2: Servicios TI | P2: Repos AV | Q2: Canje AV | R2: Canje MV | S2: Canje BV | T2: Extra / Transc AV | U2: Extra / Transc MV | V2: Extra / Transc BV | W2: TMA AV | X2: TMA MV | Y2: TMA BV | Z2: Seguro | AA2: Financia | AB2: Prepago | AC2: MultiSIM | AD2: Alta ADSL / F300 | AE2: Alta F300 / Migra F300 | AF2: Contr. AV / Migras | AG2: Alta / Porta | AH2: Repos. Tarifas | AI2: Alta BAF / MFE | AJ2: Migra F300 / MFE | AK2: Alta / Migra BAF / MFE | AL2: Alta MFE / Migra MFE | AM2: TMA | AN2: Servicio TI | AO2: Aportación Terminal | AP2: Caja Terminal | AQ2: Banco Financia | AR2: Recicla | AS2: Caja Tarjeta SIM | AT2: Caja Accesorio | AU2: Caja Recarga | AV2: PRV PDV | AW2: PRV FFVV | AX2: Pre-Liq PRV FFVV | AY2: Ingresos
A3: ENE | B3: Estación | C3: =SUM(D3:AY3) -> 28734.17 | D3: 646 | E3: 714 | F3: - | G3: 300 | H3: 108 | I3: - | J3: 0 | K3: 400 | L3: 434 | M3: - | N3: - | O3: - | P3: - | Q3: 375 | R3: 450 | S3: 0 | T3: 75 | U3: 120 | V3: 0 | W3: - | X3: - | Y3: - | Z3: 70 | AA3: 231 | AB3: 635 | AC3: 63 | AD3: 285 | AE3: 252 | AF3: 615 | AG3: - | AH3: - | AI3: - | AJ3: - | AK3: - | AL3: - | AM3: - | AN3: - | AO3: 2955.59 | AP3: 6992.64 | AQ3: 8241.43 | AR3: 186.24 | AS3: 242.98 | AT3: 506.77 | AU3: 297.52 | AV3: 3538 | AW3: - | AX3: - | AY3: -
B4: Correhuela | C4: =SUM(D4:AY4) -> 32814.5 | D4: 462 | E4: 568 | F4: - | G4: 240 | H4: 96 | I4: - | J4: 0 | K4: 180 | L4: 416 | M4: - | N4: - | O4: - | P4: - | Q4: 775 | R4: 390 | S4: 10 | T4: 75 | U4: 36 | V4: 0 | W4: - | X4: - | Y4: - | Z4: 7 | AA4: 231 | AB4: 665 | AC4: 35 | AD4: 255 | AE4: 168 | AF4: 360 | AG4: - | AH4: - | AI4: - | AJ4: - | AK4: - | AL4: - | AM4: - | AN4: - | AO4: 3671.37 | AP4: 7624.45 | AQ4: 12466.41 | AR4: 6.24 | AS4: 257.85 | AT4: 559.9 | AU4: 446.28 | AV4: 2813 | AW4: - | AX4: - | AY4: -
B5: Santa Marta | C5: =SUM(D5:AY5) -> 17896.4 | D5: 524 | E5: 680 | F5: - | G5: 130 | H5: 84 | I5: - | J5: 50 | K5: 68 | L5: 260 | M5: - | N5: - | O5: - | P5: - | Q5: 200 | R5: 315 | S5: 10 | T5: 50 | U5: 15 | V5: 0 | W5: - | X5: - | Y5: - | Z5: 126 | AA5: 126 | AB5: 488.75 | AC5: 0 | AD5: 240 | AE5: 196 | AF5: 540 | AG5: - | AH5: - | AI5: - | AJ5: - | AK5: - | AL5: - | AM5: - | AN5: - | AO5: 1567.06 | AP5: 2279.75 | AQ5: 6718.18 | AR5: 6.24 | AS5: 102.48 | AT5: 472.6 | AU5: 338.84 | AV5: 2308.5 | AW5: - | AX5: - | AY5: -
B6: Peñaranda | C6: =SUM(D6:AY6) -> 17654.37 | D6: 296 | E6: 252 | F6: - | G6: 252 | H6: 12 | I6: - | J6: 50 | K6: 80 | L6: 164 | M6: - | N6: - | O6: - | P6: - | Q6: 225 | R6: 240 | S6: 10 | T6: 0 | U6: 30 | V6: 0 | W6: - | X6: - | Y6: - | Z6: 42 | AA6: 112 | AB6: 395 | AC6: 7 | AD6: 165 | AE6: 14 | AF6: 285 | AG6: - | AH6: - | AI6: - | AJ6: - | AK6: - | AL6: - | AM6: - | AN6: - | AO6: 2031.45 | AP6: 4910.82 | AQ6: 4351.9 | AR6: 6.24 | AS6: 196.96 | AT6: 475 | AU6: 719 | AV6: 2332 | AW6: - | AX6: - | AY6: -
B7: Vitigudino | C7: =SUM(D7:AY7) -> 19223.91 | D7: 544 | E7: 480 | F7: - | G7: 260 | H7: 0 | I7: - | J7: 200 | K7: 60 | L7: 324 | M7: - | N7: - | O7: - | P7: - | Q7: 200 | R7: 405 | S7: 0 | T7: 0 | U7: 30 | V7: 0 | W7: - | X7: - | Y7: - | Z7: 14 | AA7: 119 | AB7: 775.5 | AC7: 7 | AD7: 285 | AE7: 0 | AF7: 390 | AG7: - | AH7: - | AI7: - | AJ7: - | AK7: - | AL7: - | AM7: - | AN7: - | AO7: 2731.62 | AP7: 5085.03 | AQ7: 3680 | AR7: 6.24 | AS7: 89.25 | AT7: 427.18 | AU7: 628.09 | AV7: 2483 | AW7: - | AX7: - | AY7: -
B8: Básico GVT | C8: =SUM(D8:AY8) -> 7536.88 | D8: 230 | E8: 92 | F8: 665 | G8: 10 | H8: - | I8: 20 | J8: - | K8: - | L8: - | M8: 55 | N8: 0 | O8: 62 | P8: 60 | Q8: - | R8: - | S8: - | T8: - | U8: - | V8: - | W8: 75 | X8: 0 | Y8: 0 | Z8: - | AA8: - | AB8: - | AC8: - | AD8: - | AE8: - | AF8: - | AG8: 1136 | AH8: 20 | AI8: 262.5 | AJ8: 60 | AK8: - | AL8: 100 | AM8: - | AN8: 159 | AO8: 866.94 | AP8: 156.83 | AQ8: - | AR8: - | AS8: 6.61 | AT8: 0 | AU8: - | AV8: - | AW8: 3150 | AX8: 350 | AY8: -
B9: Básico XCU | C9: =SUM(D9:AY9) -> 0 | D9: N/D | E9: N/D | F9: N/D | G9: N/D | H9: - | I9: N/D | J9: - | K9: - | L9: - | M9: N/D | N9: N/D | O9: N/D | P9: N/D | Q9: - | R9: - | S9: - | T9: - | U9: - | V9: - | W9: N/D | X9: N/D | Y9: N/D | Z9: - | AA9: - | AB9: - | AC9: - | AD9: - | AE9: - | AF9: - | AG9: N/D | AH9: N/D | AI9: N/D | AJ9: N/D | AK9: - | AL9: N/D | AM9: - | AN9: N/D | AQ9: - | AR9: - | AU9: - | AV9: - | AW9: N/D | AX9: N/D | AY9: -
B10: Plus NFG | C10: =SUM(D10:AY10) -> 5652.2 | D10: 10 | E10: 0 | F10: 130 | G10: 10 | H10: - | I10: 40 | J10: - | K10: - | L10: - | M10: 0 | N10: 90 | O10: 60 | P10: 5 | Q10: - | R10: - | S10: - | T10: - | U10: - | V10: - | W10: 200 | X10: 0 | Y10: 0 | Z10: - | AA10: - | AB10: - | AC10: - | AD10: - | AE10: - | AF10: - | AG10: 135 | AH10: 40 | AI10: 84 | AJ10: 120 | AK10: - | AL10: 100 | AM10: - | AN10: 180 | AQ10: - | AR10: - | AU10: - | AV10: - | AW10: 3048.2 | AX10: 1400 | AY10: -
B11: Plus N7D | C11: =SUM(D11:AY11) -> 6406.2 | D11: 130 | E11: 40 | F11: 100 | G11: 0 | H11: - | I11: 10 | J11: - | K11: - | L11: - | M11: 0 | N11: 90 | O11: 60 | P11: 100 | Q11: - | R11: - | S11: - | T11: - | U11: - | V11: - | W11: 0 | X11: 54 | Y11: 10 | Z11: - | AA11: - | AB11: - | AC11: - | AD11: - | AE11: - | AF11: - | AG11: 804 | AH11: 120 | AI11: 150 | AJ11: 10 | AK11: - | AL11: 100 | AM11: - | AN11: 180 | AQ11: - | AR11: - | AU11: - | AV11: - | AW11: 3048.2 | AX11: 1400 | AY11: -
B12: Plus K2Z | C12: =SUM(D12:AY12) -> 4922.2 | D12: 0 | E12: 0 | F12: 0 | G12: 0 | H12: - | I12: 20 | J12: - | K12: - | L12: - | M12: 0 | N12: 0 | O12: 80 | P12: 40 | Q12: - | R12: - | S12: - | T12: - | U12: - | V12: - | W12: 75 | X12: 0 | Y12: 0 | Z12: - | AA12: - | AB12: - | AC12: - | AD12: - | AE12: - | AF12: - | AG12: 0 | AH12: 40 | AI12: 0 | AJ12: 30 | AK12: - | AL12: 0 | AM12: - | AN12: 189 | AQ12: - | AR12: - | AU12: - | AV12: - | AW12: 3048.2 | AX12: 1400 | AY12: -
B13: Total | C13: =SUM(C3:C12)+AY13 -> 143930.83 | D13: =SUM(D3:D12) -> 2842 | E13: =SUM(E3:E12) -> 2826 | F13: =SUM(F3:F12) -> 895 | G13: =SUM(G3:G12) -> 1202 | H13: =SUM(H3:H12) -> 300 | I13: =SUM(I3:I12) -> 90 | J13: =SUM(J3:J12) -> 300 | K13: =SUM(K3:K12) -> 788 | ... AL13: =SUM(AL3:AL12) -> 300 | AM13: 0 | AN13: =SUM(AN3:AN12) -> 708 | AO13: =SUM(AO3:AO12) -> 13824.03 | AP13: =SUM(AP3:AP12) -> 27049.52 | AQ13: =SUM(AQ3:AQ12) -> 35457.92 | AR13: =SUM(AR3:AR12) -> 211.2 | AS13: =SUM(AS3:AS12) -> 896.13 | AT13: =SUM(AT3:AT12) -> 2441.45 | AU13: =SUM(AU3:AU12) -> 2429.73 | ... AX13: =SUM(AX3:AX12) -> 4550 | AY13: 3090
A14: FEB | B14: Estación | C14: =SUM(D14:AY14) -> 23601.83 | D14: 526 | E14: 578 | F14: - | G14: 450 | H14: 84 | I14: - | J14: 50 | K14: 13 | L14: 105 | M14: - | N14: - | O14: - | P14: - | Q14: 425 | R14: 405 | S14: 5 | T14: 25 | U14: 45 | V14: 22 | W14: - | X14: - | Y14: - | Z14: 140 | AA14: 220 | AB14: 267 | AC14: 53 | AD14: 225 | AE14: 210 | AF14: 375 | AG14: - | AH14: - | AI14: - | AJ14: - | AK14: - | AL14: - | AM14: - | AN14: - | AO14: 3472.5 | AP14: 4747.97 | AQ14: 6310.08 | AR14: 0 | AS14: 106.61 | AT14: 782.19 | AU14: 421.48 | AV14: 3538 | AW14: - | AX14: - | AY14: -
B15: Correhuela | C15: =SUM(D15:AY15) -> 18088.94 | D15: 441 | E15: 447 | F15: - | G15: 239 | H15: 72 | I15: - | J15: 0 | K15: 16 | L15: 0 | M15: - | N15: - | O15: - | P15: - | Q15: 400 | R15: 285 | S15: 0 | T15: 0 | U15: 45 | V15: 15 | W15: - | X15: - | Y15: - | Z15: 21 | AA15: 98 | AB15: 199.75 | AC15: 60 | AD15: 255 | AE15: 140 | AF15: 270 | AG15: - | AH15: - | AI15: - | AJ15: - | AK15: - | AL15: - | AM15: - | AN15: - | AO15: 3156.32 | AP15: 5056.19 | AQ15: 3227.68 | AR15: 0 | AS15: 125.62 | AT15: 375.81 | AU15: 330.57 | AV15: 2813 | AW15: - | AX15: - | AY15: -
B16: Santa Marta | C16: =SUM(D16:AY16) -> 14823.5 | D16: 308 | E16: 532 | F16: - | G16: 335 | H16: 72 | I16: - | J16: 200 | K16: 40 | L16: 90 | M16: - | N16: - | O16: - | P16: - | Q16: 150 | R16: 300 | S16: 15 | T16: 0 | U16: 60 | V16: 45 | W16: - | X16: - | Y16: - | Z16: 112 | AA16: 112 | AB16: 226.5 | AC16: 50 | AD16: 180 | AE16: 126 | AF16: 360 | AG16: - | AH16: - | AI16: - | AJ16: - | AK16: - | AL16: - | AM16: - | AN16: - | AO16: 2059.29 | AP16: 2126.28 | AQ16: 4069.58 | AR16: 0 | AS16: 85.95 | AT16: 306.38 | AU16: 297.52 | AV16: 2565 | AW16: - | AX16: - | AY16: -
B17: Peñaranda | C17: =SUM(D17:AY17) -> 9368.1 | D17: 498 | E17: 267 | F17: - | G17: 248 | H17: 0 | I17: - | J17: 150 | K17: 60 | L17: 192 | M17: - | N17: - | O17: - | P17: - | Q17: 50 | R17: 135 | S17: 10 | T17: 25 | U17: 15 | V17: 5 | W17: - | X17: - | Y17: - | Z17: 42 | AA17: 28 | AB17: 132.25 | AC17: 20 | AD17: 270 | AE17: 0 | AF17: 0 | AG17: - | AH17: - | AI17: - | AJ17: - | AK17: - | AL17: - | AM17: - | AN17: - | AO17: 982.36 | AP17: 2302.47 | AQ17: 585.12 | AR17: 0 | AS17: 119 | AT17: 180.9 | AU17: 719 | AV17: 2332 | AW17: - | AX17: - | AY17: -
B18: Vitigudino | C18: =SUM(D18:AY18) -> 15767.35 | D18: 510 | E18: 418 | F18: - | G18: 360 | H18: 24 | I18: - | J18: 100 | K18: 100 | L18: 98 | M18: - | N18: - | O18: - | P18: - | Q18: 100 | R18: 585 | S18: 10 | T18: 25 | U18: 45 | V18: 0 | W18: - | X18: - | Y18: - | Z18: 63 | AA18: 56 | AB18: 205.25 | AC18: 20 | AD18: 255 | AE18: 28 | AF18: 0 | AG18: - | AH18: - | AI18: - | AJ18: - | AK18: - | AL18: - | AM18: - | AN18: - | AO18: 3487.37 | AP18: 4543.71 | AQ18: 1112.39 | AR18: 0 | AS18: 99.17 | AT18: 349.38 | AU18: 690.08 | AV18: 2483 | AW18: - | AX18: - | AY18: -
